Workbook
Name lst_Canal: Inicio!$E$5:$E$13
Name lst_StatusPago: Inicio!$F$5:$F$9
Name lst_EstadoCliente: Inicio!$G$5:$G$8
Name lst_Frecuencia: Inicio!$K$5:$K$7
Name rng_PDV: Clientes_PDV!$A$2:$A$250
Name rng_SKU: Maestro_SKU!$A$2:$A$500
Name cfg_IVA: Inicio!$B$13
Name cfg_VentaRecienteDias: Inicio!$B$14
Name cfg_VentaBaja: Inicio!$B$15
Name cfg_StockCritico: Inicio!$B$16
Name cfg_StockObservar: Inicio!$B$17
Name cfg_MontoPendiente: Inicio!$B$18
Name cfg_DiasVencer: Inicio!$B$19
Name cfg_AnioResumen: Resumen!$B$3
Name cfg_DiasCobertura: Inicio!$B$29
Name cfg_PctSeguridad: Inicio!$B$30
Name cfg_VentanaDemanda: Inicio!$B$31
Name cfg_VentaAlta: Inicio!$B$34

Sheet Inicio
A1: NUVA OXI | Control comercial simple
A2: GUÍA — cómo funciona, se edita, se alimenta y crece (clic aquí)
A3: Cómo se usa en simple | E3: Listas editables para desplegables
A4: 1 | B4: Dashboard: mirar cada lunes qué está en rojo o prioridad alta. | E4: Canal | F4: Status pago | G4: Estado cliente | H4: Condición pago | I4: Prioridad | J4: Estado stock | K4: Frecuencia
A5: 2 | B5: Cobertura: revisar el detalle por punto de venta, visita, venta, pago y stock. | E5: Retail | F5: Pendiente | G5: Activo | H5: Contado | I5: Alta | J5: Crítico | K5: Semanal
A6: 3 | B6: Clientes_PDV: agregar nuevos clientes o salas. Esa hoja alimenta Cobertura. | E6: Conveniencia | F6: Pagada | G6: Pausado | H6: Crédito 15 días | I6: Media | J6: Observar | K6: Quincenal
A7: 4 | B7: Ventas_SellIn: ingresar facturas reales. No usar PVP; solo precio neto facturado. | E7: Farmacias | F7: Parcial | G7: Prospecto | H7: Crédito 30 días | I7: Baja | J7: OK | K7: Mensual
A8: 5 | B8: Margen_Frontal: simular precio/margen aparte, sin afectar ventas ni cobertura. | E8: Especializadas | F8: Vencida | G8: Inactivo | H8: Crédito 45 días
A9: 6 | B9: SellOut_Jumbo: pegar exportaciones futuras de Cencosud/Jumbo cuando existan. | E9: HORECA | F9: Nota crédito | H9: Crédito 60 días
E10: Tradicional
A11: Condiciones editables | E11: Ecommerce
A12: Condición | B12: Valor editable | C12: Qué significa | E12: Corporativo
A13: IVA | B13: 0.19 | C13: Se usa para pasar neto a bruto y viceversa. | E13: Distribuidor
A14: Venta reciente últimos días | B14: 30 | C14: Período usado en cobertura y dashboard.
A15: Venta baja si es menor a | B15: 50000 | C15: Si venta neta 30d queda bajo este monto, se marca baja. | E15: Leyenda
A16: Stock crítico PDV barras | B16: 8 | C16: Barras equivalentes en sala bajo este nivel = crítico. | E16: Amarillo | F16: Dato editable
A17: Stock en observación PDV barras | B17: 20 | C17: Barras equivalentes en sala bajo este nivel = observar. | E17: Gris | F17: Fórmula; no tocar
A18: Monto pendiente relevante | B18: 100000 | C18: Deuda sobre este monto eleva prioridad. | E18: Morado | F18: Título/encabezado
A19: Factura próxima a vencer días | B19: 7 | C19: Días hacia adelante para marcar próxima a vencer.
A22: Frecuencia de visita
A23: Frecuencia | B23: Días máximos | C23: Regla
A24: Semanal | B24: 7 | C24: Atrasado desde 8 días
A25: Quincenal | B25: 15 | C25: Atrasado desde 16 días
A26: Mensual | B26: 30 | C26: Atrasado desde 31 días
A28: Parámetros de inventario (editable)
A29: Días de cobertura objetivo | B29: 30 | C29: Cuántos días de venta quieres tener en stock
A30: % stock de seguridad | B30: 0.2 | C30: Colchón sobre el objetivo ante quiebres
A31: Ventana de demanda (días) | B31: 30 | C31: Período de sell-in para el promedio (30/60/90)
A33: Reglas de rotación (editable)
A34: Rotación ALTA: venta 30d ≥ | B34: 150000 | C34: Sobre este monto, el PDV rota bien
A35: Rotación BAJA: venta 30d < | B35: =B15 | C35: Usa el mismo umbral de 'Venta baja' (B15)
A36: Rotación MEDIA: | B36: entre ambos | C36: Entre el monto de BAJA y el de ALTA

Sheet Guia_Ana
A1: Guía rápida para Ana | Cómo leer y cargar el archivo
A3: Objetivo del archivo
A4: Ayudar a decidir cada lunes qué puntos de venta visitar, cuáles están vendiendo, cuáles tienen facturas pendientes y dónde falta stock. No busca reemplazar ERP ni contabilidad.
A6: Qué mirar primero
A7: • | B7: 1. Abrir Dashboard y revisar prioridad alta.
A8: • | B8: 2. Ir a Cobertura para ver la razón: visita atrasada, sin venta, deuda o stock crítico.
A9: • | B9: 3. Filtrar por Canal o Cliente si se saldrá a terreno por zona/cuenta.
A11: Dónde cargar información
A12: • | B12: Clientes nuevos o nuevas salas: Clientes_PDV.
A13: • | B13: Facturas/sell-in: Ventas_SellIn. Ingresar fecha, factura, PDV_ID, SKU, cantidad, precio neto facturado y status de pago.
A14: • | B14: Stock observado en terreno: Stock_PDV.
A15: • | B15: Sell-out de Jumbo/Cencosud: SellOut_Jumbo, cuando exista exportación.
A16: • | B16: Simulación de precio y margen: Margen_Frontal.
A18: Regla de colores
A19: • | B19: Amarillo = se puede editar.
A20: • | B20: Gris = fórmula, mejor no tocar.
A21: • | B21: Morado = encabezado o título.
A22: • | B22: Si algo sale raro, revisar primero si falta PDV_ID, SKU o fecha.
A24: Conceptos simples
A25: • | B25: Sell-in: venta facturada al cliente o punto de venta.
A26: • | B26: Sell-out: venta desde la sala hacia consumidor final, cuando el retailer la informe.
A27: • | B27: Margen frontal: margen que el cliente obtiene entre el PVP neto y el precio neto que le facturamos.
A28: • | B28: Barras equivalentes: convierte unidades, estuches y cajas master a barras para comparar stock y venta.
A30: Cómo se edita, se alimenta y crece
A31: 1. | B31: Editar: solo celdas AMARILLAS. Las grises son fórmulas (se calculan solas).
A32: 2. | B32: Alimentar ventas: Ventas_SellIn, una fila por factura (usa los desplegables).
A33: 3. | B33: Terreno: registra visitas y stock de sala en Clientes_PDV y Stock_PDV.
A34: 4. | B34: Producto nuevo: agrégalo en Maestro_SKU; aparece solo en el plan y en las listas.
A35: 5. | B35: Cliente/sala nueva: agrégala en Clientes_PDV; aparece sola en Cobertura.
A36: 6. | B36: Inventario: escribe tu bodega en Plan_Inventario; te dice cuánto reponer.
A37: 7. | B37: Ajustes: cambia umbrales (venta, stock, cobertura, rotación) en Inicio, sin tocar fórmulas.
A38: 8. | B38: Crece hasta: 250 clientes/PDV y 800 facturas. Para más, se estiran los rangos.

Sheet Dashboard
A1: Dashboard semanal | Revisión lunes
A3: Indicador | B3: Valor | D3: Condiciones activas | E3: Valor
A4: Fecha control | B4: =TODAY() | D4: Venta reciente días | E4: =Inicio!B14
A5: PDV activos | B5: =COUNTIF(Clientes_PDV!$I$2:$I$250,"Activo") | D5: Venta baja menor a | E5: =Inicio!B15
A6: PDV prioridad alta | B6: =COUNTIF(Cobertura!$Q$2:$Q$250,"Alta") | D6: Semanal días | E6: =Inicio!B24
A7: Venta sell-in 30d neta | B7: =SUM(Cobertura!$I$2:$I$250) | D7: Quincenal días | E7: =Inicio!B25
A8: Monto pendiente | B8: =SUM(Cobertura!$M$2:$M$250) | D8: Mensual días | E8: =Inicio!B26
A9: PDV stock crítico | B9: =COUNTIF(Cobertura!$P$2:$P$250,"Crítico") | D9: Factura próxima a vencer | E9: =Inicio!B19
A11: ⚙ Ir a Configuración (hoja Inicio)
A12: Lista de gestión sugerida (filtrar en Cobertura si necesitas detalle)
A13: PDV | B13: Cliente | C13: Canal | D13: Estado visita | E13: Estado venta | F13: Estado pago | G13: Estado stock | H13: Prioridad
A14: =Cobertura!D2 | B14: =Cobertura!B2 | C14: =Cobertura!C2 | D14: =Cobertura!H2 | E14: =Cobertura!K2 | F14: =Cobertura!N2 | G14: =Cobertura!P2 | H14: =Cobertura!Q2
A15: =Cobertura!D3 | B15: =Cobertura!B3 | C15: =Cobertura!C3 | D15: =Cobertura!H3 | E15: =Cobertura!K3 | F15: =Cobertura!N3 | G15: =Cobertura!P3 | H15: =Cobertura!Q3
A16: =Cobertura!D4 | B16: =Cobertura!B4 | C16: =Cobertura!C4 | D16: =Cobertura!H4 | E16: =Cobertura!K4 | F16: =Cobertura!N4 | G16: =Cobertura!P4 | H16: =Cobertura!Q4
A17: =Cobertura!D5 | B17: =Cobertura!B5 | C17: =Cobertura!C5 | D17: =Cobertura!H5 | E17: =Cobertura!K5 | F17: =Cobertura!N5 | G17: =Cobertura!P5 | H17: =Cobertura!Q5
A18: =Cobertura!D6 | B18: =Cobertura!B6 | C18: =Cobertura!C6 | D18: =Cobertura!H6 | E18: =Cobertura!K6 | F18: =Cobertura!N6 | G18: =Cobertura!P6 | H18: =Cobertura!Q6
A19: =Cobertura!D7 | B19: =Cobertura!B7 | C19: =Cobertura!C7 | D19: =Cobertura!H7 | E19: =Cobertura!K7 | F19: =Cobertura!N7 | G19: =Cobertura!P7 | H19: =Cobertura!Q7
A20: =Cobertura!D8 | B20: =Cobertura!B8 | C20: =Cobertura!C8 | D20: =Cobertura!H8 | E20: =Cobertura!K8 | F20: =Cobertura!N8 | G20: =Cobertura!P8 | H20: =Cobertura!Q8
A21: =Cobertura!D9 | B21: =Cobertura!B9 | C21: =Cobertura!C9 | D21: =Cobertura!H9 | E21: =Cobertura!K9 | F21: =Cobertura!N9 | G21: =Cobertura!P9 | H21: =Cobertura!Q9
A22: =Cobertura!D10 | B22: =Cobertura!B10 | C22: =Cobertura!C10 | D22: =Cobertura!H10 | E22: =Cobertura!K10 | F22: =Cobertura!N10 | G22: =Cobertura!P10 | H22: =Cobertura!Q10
A23: =Cobertura!D11 | B23: =Cobertura!B11 | C23: =Cobertura!C11 | D23: =Cobertura!H11 | E23: =Cobertura!K11 | F23: =Cobertura!N11 | G23: =Cobertura!P11 | H23: =Cobertura!Q11
A24: =Cobertura!D12 | B24: =Cobertura!B12 | C24: =Cobertura!C12 | D24: =Cobertura!H12 | E24: =Cobertura!K12 | F24: =Cobertura!N12 | G24: =Cobertura!P12 | H24: =Cobertura!Q12
A25: =Cobertura!D13 | B25: =Cobertura!B13 | C25: =Cobertura!C13 | D25: =Cobertura!H13 | E25: =Cobertura!K13 | F25: =Cobertura!N13 | G25: =Cobertura!P13 | H25: =Cobertura!Q13

Sheet Resumen
A1: RESUMEN | Nuva Oxi
A3: Año de análisis: | B3: 2026 | D3: ⚙ Configuración
A5: Seguimiento — terreno vs escritorio | D5: Venta por mes (año en B3)
A6: Indicador | B6: Valor | D6: Periodo | E6: Venta neta | F6: Unidades | G6: Monto pend.
A7: PDV activos | B7: =COUNTIF(Clientes_PDV!$I$2:$I$250,"Activo") | D7: =$B$3&"-"&TEXT(1,"00") | E7: =SUMIFS(Ventas_SellIn!$L$2:$L$800,Ventas_SellIn!$X$2:$X$800,$D7) | F7: =SUMIFS(Ventas_SellIn!$J$2:$J$800,Ventas_SellIn!$X$2:$X$800,$D7) | G7: =SUMIFS(Ventas_SellIn!$R$2:$R$800,Ventas_SellIn!$X$2:$X$800,$D7)
A8: Visita vigente | B8: =COUNTIF(Cobertura!$H$2:$H$250,"Vigente") | D8: =$B$3&"-"&TEXT(2,"00") | E8: =SUMIFS(Ventas_SellIn!$L$2:$L$800,Ventas_SellIn!$X$2:$X$800,$D8) | F8: =SUMIFS(Ventas_SellIn!$J$2:$J$800,Ventas_SellIn!$X$2:$X$800,$D8) | G8: =SUMIFS(Ventas_SellIn!$R$2:$R$800,Ventas_SellIn!$X$2:$X$800,$D8)
A9: Visita atrasada | B9: =COUNTIF(Cobertura!$H$2:$H$250,"Atrasado") | D9: =$B$3&"-"&TEXT(3,"00") | E9: =SUMIFS(Ventas_SellIn!$L$2:$L$800,Ventas_SellIn!$X$2:$X$800,$D9) | F9: =SUMIFS(Ventas_SellIn!$J$2:$J$800,Ventas_SellIn!$X$2:$X$800,$D9) | G9: =SUMIFS(Ventas_SellIn!$R$2:$R$800,Ventas_SellIn!$X$2:$X$800,$D9)
A10: Sin visita | B10: =COUNTIF(Cobertura!$H$2:$H$250,"Sin visita") | D10: =$B$3&"-"&TEXT(4,"00") | E10: =SUMIFS(Ventas_SellIn!$L$2:$L$800,Ventas_SellIn!$X$2:$X$800,$D10) | F10: =SUMIFS(Ventas_SellIn!$J$2:$J$800,Ventas_SellIn!$X$2:$X$800,$D10) | G10: =SUMIFS(Ventas_SellIn!$R$2:$R$800,Ventas_SellIn!$X$2:$X$800,$D10)
A11: PDV con venta OK | B11: =COUNTIF(Cobertura!$K$2:$K$250,"Venta OK") | D11: =$B$3&"-"&TEXT(5,"00") | E11: =SUMIFS(Ventas_SellIn!$L$2:$L$800,Ventas_SellIn!$X$2:$X$800,$D11) | F11: =SUMIFS(Ventas_SellIn!$J$2:$J$800,Ventas_SellIn!$X$2:$X$800,$D11) | G11: =SUMIFS(Ventas_SellIn!$R$2:$R$800,Ventas_SellIn!$X$2:$X$800,$D11)
A12: PDV venta baja | B12: =COUNTIF(Cobertura!$K$2:$K$250,"Venta baja") | D12: =$B$3&"-"&TEXT(6,"00") | E12: =SUMIFS(Ventas_SellIn!$L$2:$L$800,Ventas_SellIn!$X$2:$X$800,$D12) | F12: =SUMIFS(Ventas_SellIn!$J$2:$J$800,Ventas_SellIn!$X$2:$X$800,$D12) | G12: =SUMIFS(Ventas_SellIn!$R$2:$R$800,Ventas_SellIn!$X$2:$X$800,$D12)
A13: PDV sin venta | B13: =COUNTIF(Cobertura!$K$2:$K$250,"Sin venta") | D13: =$B$3&"-"&TEXT(7,"00") | E13: =SUMIFS(Ventas_SellIn!$L$2:$L$800,Ventas_SellIn!$X$2:$X$800,$D13) | F13: =SUMIFS(Ventas_SellIn!$J$2:$J$800,Ventas_SellIn!$X$2:$X$800,$D13) | G13: =SUMIFS(Ventas_SellIn!$R$2:$R$800,Ventas_SellIn!$X$2:$X$800,$D13)
A14: Prioridad Alta (lunes) | B14: =COUNTIF(Cobertura!$Q$2:$Q$250,"Alta") | D14: =$B$3&"-"&TEXT(8,"00") | E14: =SUMIFS(Ventas_SellIn!$L$2:$L$800,Ventas_SellIn!$X$2:$X$800,$D14) | F14: =SUMIFS(Ventas_SellIn!$J$2:$J$800,Ventas_SellIn!$X$2:$X$800,$D14) | G14: =SUMIFS(Ventas_SellIn!$R$2:$R$800,Ventas_SellIn!$X$2:$X$800,$D14)
A15: Monto pendiente total | B15: =SUM(Cobertura!$M$2:$M$250) | D15: =$B$3&"-"&TEXT(9,"00") | E15: =SUMIFS(Ventas_SellIn!$L$2:$L$800,Ventas_SellIn!$X$2:$X$800,$D15) | F15: =SUMIFS(Ventas_SellIn!$J$2:$J$800,Ventas_SellIn!$X$2:$X$800,$D15) | G15: =SUMIFS(Ventas_SellIn!$R$2:$R$800,Ventas_SellIn!$X$2:$X$800,$D15)
D16: =$B$3&"-"&TEXT(10,"00") | E16: =SUMIFS(Ventas_SellIn!$L$2:$L$800,Ventas_SellIn!$X$2:$X$800,$D16) | F16: =SUMIFS(Ventas_SellIn!$J$2:$J$800,Ventas_SellIn!$X$2:$X$800,$D16) | G16: =SUMIFS(Ventas_SellIn!$R$2:$R$800,Ventas_SellIn!$X$2:$X$800,$D16)
D17: =$B$3&"-"&TEXT(11,"00") | E17: =SUMIFS(Ventas_SellIn!$L$2:$L$800,Ventas_SellIn!$X$2:$X$800,$D17) | F17: =SUMIFS(Ventas_SellIn!$J$2:$J$800,Ventas_SellIn!$X$2:$X$800,$D17) | G17: =SUMIFS(Ventas_SellIn!$R$2:$R$800,Ventas_SellIn!$X$2:$X$800,$D17)
D18: =$B$3&"-"&TEXT(12,"00") | E18: =SUMIFS(Ventas_SellIn!$L$2:$L$800,Ventas_SellIn!$X$2:$X$800,$D18) | F18: =SUMIFS(Ventas_SellIn!$J$2:$J$800,Ventas_SellIn!$X$2:$X$800,$D18) | G18: =SUMIFS(Ventas_SellIn!$R$2:$R$800,Ventas_SellIn!$X$2:$X$800,$D18)
A19: Nota: se llena solo desde Ventas_SellIn y Cobertura. Cambia el año en B3. | D19: TOTAL | E19: =SUM(E7:E18) | F19: =SUM(F7:F18) | G19: =SUM(G7:G18)
A21: Venta por canal
A22: Canal | B22: Venta neta | C22: Unidades
A23: =Inicio!$E$5 | B23: =IF($A23="","",SUMIFS(Ventas_SellIn!$L$2:$L$800,Ventas_SellIn!$F$2:$F$800,$A23)) | C23: =IF($A23="","",SUMIFS(Ventas_SellIn!$J$2:$J$800,Ventas_SellIn!$F$2:$F$800,$A23))
A24: =Inicio!$E$6 | B24: =IF($A24="","",SUMIFS(Ventas_SellIn!$L$2:$L$800,Ventas_SellIn!$F$2:$F$800,$A24)) | C24: =IF($A24="","",SUMIFS(Ventas_SellIn!$J$2:$J$800,Ventas_SellIn!$F$2:$F$800,$A24))
A25: =Inicio!$E$7 | B25: =IF($A25="","",SUMIFS(Ventas_SellIn!$L$2:$L$800,Ventas_SellIn!$F$2:$F$800,$A25)) | C25: =IF($A25="","",SUMIFS(Ventas_SellIn!$J$2:$J$800,Ventas_SellIn!$F$2:$F$800,$A25))
A26: =Inicio!$E$8 | B26: =IF($A26="","",SUMIFS(Ventas_SellIn!$L$2:$L$800,Ventas_SellIn!$F$2:$F$800,$A26)) | C26: =IF($A26="","",SUMIFS(Ventas_SellIn!$J$2:$J$800,Ventas_SellIn!$F$2:$F$800,$A26))
A27: =Inicio!$E$9 | B27: =IF($A27="","",SUMIFS(Ventas_SellIn!$L$2:$L$800,Ventas_SellIn!$F$2:$F$800,$A27)) | C27: =IF($A27="","",SUMIFS(Ventas_SellIn!$J$2:$J$800,Ventas_SellIn!$F$2:$F$800,$A27))
A28: =Inicio!$E$10 | B28: =IF($A28="","",SUMIFS(Ventas_SellIn!$L$2:$L$800,Ventas_SellIn!$F$2:$F$800,$A28)) | C28: =IF($A28="","",SUMIFS(Ventas_SellIn!$J$2:$J$800,Ventas_SellIn!$F$2:$F$800,$A28))
A29: =Inicio!$E$11 | B29: =IF($A29="","",SUMIFS(Ventas_SellIn!$L$2:$L$800,Ventas_SellIn!$F$2:$F$800,$A29)) | C29: =IF($A29="","",SUMIFS(Ventas_SellIn!$J$2:$J$800,Ventas_SellIn!$F$2:$F$800,$A29))
A30: =Inicio!$E$12 | B30: =IF($A30="","",SUMIFS(Ventas_SellIn!$L$2:$L$800,Ventas_SellIn!$F$2:$F$800,$A30)) | C30: =IF($A30="","",SUMIFS(Ventas_SellIn!$J$2:$J$800,Ventas_SellIn!$F$2:$F$800,$A30))
A31: =Inicio!$E$13 | B31: =IF($A31="","",SUMIFS(Ventas_SellIn!$L$2:$L$800,Ventas_SellIn!$F$2:$F$800,$A31)) | C31: =IF($A31="","",SUMIFS(Ventas_SellIn!$J$2:$J$800,Ventas_SellIn!$F$2:$F$800,$A31))
A32: Tip: en Ventas_SellIn filtra la columna Fecha → Filtros de fecha → Entre… para ver el detalle.
A33: Reporte de ventas por rango de fechas
A34: Desde: | B34: 46023 | C34: Hasta: | D34: 46387
A35: Métrica | B35: Valor
A36: Venta neta (rango) | B36: =SUMIFS(Ventas_SellIn!$L$2:$L$800,Ventas_SellIn!$B$2:$B$800,">="&$B$34,Ventas_SellIn!$B$2:$B$800,"<="&$D$34)
A37: Unidades (rango) | B37: =SUMIFS(Ventas_SellIn!$J$2:$J$800,Ventas_SellIn!$B$2:$B$800,">="&$B$34,Ventas_SellIn!$B$2:$B$800,"<="&$D$34)
A38: N° facturas/líneas | B38: =COUNTIFS(Ventas_SellIn!$B$2:$B$800,">="&$B$34,Ventas_SellIn!$B$2:$B$800,"<="&$D$34,Ventas_SellIn!$A$2:$A$800,"<>")
A39: Monto pendiente (rango) | B39: =SUMIFS(Ventas_SellIn!$R$2:$R$800,Ventas_SellIn!$B$2:$B$800,">="&$B$34,Ventas_SellIn!$B$2:$B$800,"<="&$D$34)
A41: Venta por canal en el rango
A42: Canal | B42: Venta neta | C42: Unidades
A43: =Inicio!$E$5 | B43: =IF($A43="","",SUMIFS(Ventas_SellIn!$L$2:$L$800,Ventas_SellIn!$F$2:$F$800,$A43,Ventas_SellIn!$B$2:$B$800,">="&$B$34,Ventas_SellIn!$B$2:$B$800,"<="&$D$34)) | C43: =IF($A43="","",SUMIFS(Ventas_SellIn!$J$2:$J$800,Ventas_SellIn!$F$2:$F$800,$A43,Ventas_SellIn!$B$2:$B$800,">="&$B$34,Ventas_SellIn!$B$2:$B$800,"<="&$D$34))
A44: =Inicio!$E$6 | B44: =IF($A44="","",SUMIFS(Ventas_SellIn!$L$2:$L$800,Ventas_SellIn!$F$2:$F$800,$A44,Ventas_SellIn!$B$2:$B$800,">="&$B$34,Ventas_SellIn!$B$2:$B$800,"<="&$D$34)) | C44: =IF($A44="","",SUMIFS(Ventas_SellIn!$J$2:$J$800,Ventas_SellIn!$F$2:$F$800,$A44,Ventas_SellIn!$B$2:$B$800,">="&$B$34,Ventas_SellIn!$B$2:$B$800,"<="&$D$34))
...

Sheet Plan_Inventario
A1: Producto (SKU) | B1: Descripción | C1: Sell-in ventana | D1: Venta/día | E1: Stock objetivo | F1: Bodega (unid.) | G1: Bodega barras | H1: Reponer (barras) | I1: Estado | K1: ⚙ Configuración
A2: =IF(Maestro_SKU!A2="","",Maestro_SKU!A2) | B2: =IF(A2="","",IFERROR(VLOOKUP(A2,Maestro_SKU!$A$2:$P$500,2,FALSE),"")) | C2: =IF(A2="","",SUMIFS(Ventas_SellIn!$Y$2:$Y$800,Ventas_SellIn!$H$2:$H$800,A2,Ventas_SellIn!$B$2:$B$800,">="&TODAY()-cfg_VentanaDemanda)) | D2: =IF(A2="","",C2/cfg_VentanaDemanda) | E2: =IF(A2="","",ROUND(D2*cfg_DiasCobertura*(1+cfg_PctSeguridad),0)) | G2: =IF(A2="","",IF(F2="",0,F2*IFERROR(VLOOKUP(A2,Maestro_SKU!$A$2:$P$500,12,FALSE),1))) | H2: =IF(A2="","",MAX(E2-G2,0)) | I2: =IF(A2="","",IF(F2="","Falta bodega",IF(G2>=E2,"OK",IF(G2>=E2*0.6,"Ajustado","Reponer"))))
A3: =IF(Maestro_SKU!A3="","",Maestro_SKU!A3) | B3: =IF(A3="","",IFERROR(VLOOKUP(A3,Maestro_SKU!$A$2:$P$500,2,FALSE),"")) | C3: =IF(A3="","",SUMIFS(Ventas_SellIn!$Y$2:$Y$800,Ventas_SellIn!$H$2:$H$800,A3,Ventas_SellIn!$B$2:$B$800,">="&TODAY()-cfg_VentanaDemanda)) | D3: =IF(A3="","",C3/cfg_VentanaDemanda) | E3: =IF(A3="","",ROUND(D3*cfg_DiasCobertura*(1+cfg_PctSeguridad),0)) | G3: =IF(A3="","",IF(F3="",0,F3*IFERROR(VLOOKUP(A3,Maestro_SKU!$A$2:$P$500,12,FALSE),1))) | H3: =IF(A3="","",MAX(E3-G3,0)) | I3: =IF(A3="","",IF(F3="","Falta bodega",IF(G3>=E3,"OK",IF(G3>=E3*0.6,"Ajustado","Reponer"))))
A4: =IF(Maestro_SKU!A4="","",Maestro_SKU!A4) | B4: =IF(A4="","",IFERROR(VLOOKUP(A4,Maestro_SKU!$A$2:$P$500,2,FALSE),"")) | C4: =IF(A4="","",SUMIFS(Ventas_SellIn!$Y$2:$Y$800,Ventas_SellIn!$H$2:$H$800,A4,Ventas_SellIn!$B$2:$B$800,">="&TODAY()-cfg_VentanaDemanda)) | D4: =IF(A4="","",C4/cfg_VentanaDemanda) | E4: =IF(A4="","",ROUND(D4*cfg_DiasCobertura*(1+cfg_PctSeguridad),0)) | G4: =IF(A4="","",IF(F4="",0,F4*IFERROR(VLOOKUP(A4,Maestro_SKU!$A$2:$P$500,12,FALSE),1))) | H4: =IF(A4="","",MAX(E4-G4,0)) | I4: =IF(A4="","",IF(F4="","Falta bodega",IF(G4>=E4,"OK",IF(G4>=E4*0.6,"Ajustado","Reponer"))))
A5: =IF(Maestro_SKU!A5="","",Maestro_SKU!A5) | B5: =IF(A5="","",IFERROR(VLOOKUP(A5,Maestro_SKU!$A$2:$P$500,2,FALSE),"")) | C5: =IF(A5="","",SUMIFS(Ventas_SellIn!$Y$2:$Y$800,Ventas_SellIn!$H$2:$H$800,A5,Ventas_SellIn!$B$2:$B$800,">="&TODAY()-cfg_VentanaDemanda)) | D5: =IF(A5="","",C5/cfg_VentanaDemanda) | E5: =IF(A5="","",ROUND(D5*cfg_DiasCobertura*(1+cfg_PctSeguridad),0)) | G5: =IF(A5="","",IF(F5="",0,F5*IFERROR(VLOOKUP(A5,Maestro_SKU!$A$2:$P$500,12,FALSE),1))) | H5: =IF(A5="","",MAX(E5-G5,0)) | I5: =IF(A5="","",IF(F5="","Falta bodega",IF(G5>=E5,"OK",IF(G5>=E5*0.6,"Ajustado","Reponer"))))
A6: =IF(Maestro_SKU!A6="","",Maestro_SKU!A6) | B6: =IF(A6="","",IFERROR(VLOOKUP(A6,Maestro_SKU!$A$2:$P$500,2,FALSE),"")) | C6: =IF(A6="","",SUMIFS(Ventas_SellIn!$Y$2:$Y$800,Ventas_SellIn!$H$2:$H$800,A6,Ventas_SellIn!$B$2:$B$800,">="&TODAY()-cfg_VentanaDemanda)) | D6: =IF(A6="","",C6/cfg_VentanaDemanda) | E6: =IF(A6="","",ROUND(D6*cfg_DiasCobertura*(1+cfg_PctSeguridad),0)) | G6: =IF(A6="","",IF(F6="",0,F6*IFERROR(VLOOKUP(A6,Maestro_SKU!$A$2:$P$500,12,FALSE),1))) | H6: =IF(A6="","",MAX(E6-G6,0)) | I6: =IF(A6="","",IF(F6="","Falta bodega",IF(G6>=E6,"OK",IF(G6>=E6*0.6,"Ajustado","Reponer"))))
A7: =IF(Maestro_SKU!A7="","",Maestro_SKU!A7) | B7: =IF(A7="","",IFERROR(VLOOKUP(A7,Maestro_SKU!$A$2:$P$500,2,FALSE),"")) | C7: =IF(A7="","",SUMIFS(Ventas_SellIn!$Y$2:$Y$800,Ventas_SellIn!$H$2:$H$800,A7,Ventas_SellIn!$B$2:$B$800,">="&TODAY()-cfg_VentanaDemanda)) | D7: =IF(A7="","",C7/cfg_VentanaDemanda) | E7: =IF(A7="","",ROUND(D7*cfg_DiasCobertura*(1+cfg_PctSeguridad),0)) | G7: =IF(A7="","",IF(F7="",0,F7*IFERROR(VLOOKUP(A7,Maestro_SKU!$A$2:$P$500,12,FALSE),1))) | H7: =IF(A7="","",MAX(E7-G7,0)) | I7: =IF(A7="","",IF(F7="","Falta bodega",IF(G7>=E7,"OK",IF(G7>=E7*0.6,"Ajustado","Reponer"))))
A8: =IF(Maestro_SKU!A8="","",Maestro_SKU!A8) | B8: =IF(A8="","",IFERROR(VLOOKUP(A8,Maestro_SKU!$A$2:$P$500,2,FALSE),"")) | C8: =IF(A8="","",SUMIFS(Ventas_SellIn!$Y$2:$Y$800,Ventas_SellIn!$H$2:$H$800,A8,Ventas_SellIn!$B$2:$B$800,">="&TODAY()-cfg_VentanaDemanda)) | D8: =IF(A8="","",C8/cfg_VentanaDemanda) | E8: =IF(A8="","",ROUND(D8*cfg_DiasCobertura*(1+cfg_PctSeguridad),0)) | G8: =IF(A8="","",IF(F8="",0,F8*IFERROR(VLOOKUP(A8,Maestro_SKU!$A$2:$P$500,12,FALSE),1))) | H8: =IF(A8="","",MAX(E8-G8,0)) | I8: =IF(A8="","",IF(F8="","Falta bodega",IF(G8>=E8,"OK",IF(G8>=E8*0.6,"Ajustado","Reponer"))))
A9: =IF(Maestro_SKU!A9="","",Maestro_SKU!A9) | B9: =IF(A9="","",IFERROR(VLOOKUP(A9,Maestro_SKU!$A$2:$P$500,2,FALSE),"")) | C9: =IF(A9="","",SUMIFS(Ventas_SellIn!$Y$2:$Y$800,Ventas_SellIn!$H$2:$H$800,A9,Ventas_SellIn!$B$2:$B$800,">="&TODAY()-cfg_VentanaDemanda)) | D9: =IF(A9="","",C9/cfg_VentanaDemanda) | E9: =IF(A9="","",ROUND(D9*cfg_DiasCobertura*(1+cfg_PctSeguridad),0)) | G9: =IF(A9="","",IF(F9="",0,F9*IFERROR(VLOOKUP(A9,Maestro_SKU!$A$2:$P$500,12,FALSE),1))) | H9: =IF(A9="","",MAX(E9-G9,0)) | I9: =IF(A9="","",IF(F9="","Falta bodega",IF(G9>=E9,"OK",IF(G9>=E9*0.6,"Ajustado","Reponer"))))
A10: =IF(Maestro_SKU!A10="","",Maestro_SKU!A10) | B10: =IF(A10="","",IFERROR(VLOOKUP(A10,Maestro_SKU!$A$2:$P$500,2,FALSE),"")) | C10: =IF(A10="","",SUMIFS(Ventas_SellIn!$Y$2:$Y$800,Ventas_SellIn!$H$2:$H$800,A10,Ventas_SellIn!$B$2:$B$800,">="&TODAY()-cfg_VentanaDemanda)) | D10: =IF(A10="","",C10/cfg_VentanaDemanda) | E10: =IF(A10="","",ROUND(D10*cfg_DiasCobertura*(1+cfg_PctSeguridad),0)) | G10: =IF(A10="","",IF(F10="",0,F10*IFERROR(VLOOKUP(A10,Maestro_SKU!$A$2:$P$500,12,FALSE),1))) | H10: =IF(A10="","",MAX(E10-G10,0)) | I10: =IF(A10="","",IF(F10="","Falta bodega",IF(G10>=E10,"OK",IF(G10>=E10*0.6,"Ajustado","Reponer"))))
A11: =IF(Maestro_SKU!A11="","",Maestro_SKU!A11) | B11: =IF(A11="","",IFERROR(VLOOKUP(A11,Maestro_SKU!$A$2:$P$500,2,FALSE),"")) | C11: =IF(A11="","",SUMIFS(Ventas_SellIn!$Y$2:$Y$800,Ventas_SellIn!$H$2:$H$800,A11,Ventas_SellIn!$B$2:$B$800,">="&TODAY()-cfg_VentanaDemanda)) | D11: =IF(A11="","",C11/cfg_VentanaDemanda) | E11: =IF(A11="","",ROUND(D11*cfg_DiasCobertura*(1+cfg_PctSeguridad),0)) | G11: =IF(A11="","",IF(F11="",0,F11*IFERROR(VLOOKUP(A11,Maestro_SKU!$A$2:$P$500,12,FALSE),1))) | H11: =IF(A11="","",MAX(E11-G11,0)) | I11: =IF(A11="","",IF(F11="","Falta bodega",IF(G11>=E11,"OK",IF(G11>=E11*0.6,"Ajustado","Reponer"))))
A12: =IF(Maestro_SKU!A12="","",Maestro_SKU!A12) | B12: =IF(A12="","",IFERROR(VLOOKUP(A12,Maestro_SKU!$A$2:$P$500,2,FALSE),"")) | C12: =IF(A12="","",SUMIFS(Ventas_SellIn!$Y$2:$Y$800,Ventas_SellIn!$H$2:$H$800,A12,Ventas_SellIn!$B$2:$B$800,">="&TODAY()-cfg_VentanaDemanda)) | D12: =IF(A12="","",C12/cfg_VentanaDemanda) | E12: =IF(A12="","",ROUND(D12*cfg_DiasCobertura*(1+cfg_PctSeguridad),0)) | G12: =IF(A12="","",IF(F12="",0,F12*IFERROR(VLOOKUP(A12,Maestro_SKU!$A$2:$P$500,12,FALSE),1))) | H12: =IF(A12="","",MAX(E12-G12,0)) | I12: =IF(A12="","",IF(F12="","Falta bodega",IF(G12>=E12,"OK",IF(G12>=E12*0.6,"Ajustado","Reponer"))))
A13: =IF(Maestro_SKU!A13="","",Maestro_SKU!A13) | B13: =IF(A13="","",IFERROR(VLOOKUP(A13,Maestro_SKU!$A$2:$P$500,2,FALSE),"")) | C13: =IF(A13="","",SUMIFS(Ventas_SellIn!$Y$2:$Y$800,Ventas_SellIn!$H$2:$H$800,A13,Ventas_SellIn!$B$2:$B$800,">="&TODAY()-cfg_VentanaDemanda)) | D13: =IF(A13="","",C13/cfg_VentanaDemanda) | E13: =IF(A13="","",ROUND(D13*cfg_DiasCobertura*(1+cfg_PctSeguridad),0)) | G13: =IF(A13="","",IF(F13="",0,F13*IFERROR(VLOOKUP(A13,Maestro_SKU!$A$2:$P$500,12,FALSE),1))) | H13: =IF(A13="","",MAX(E13-G13,0)) | I13: =IF(A13="","",IF(F13="","Falta bodega",IF(G13>=E13,"OK",IF(G13>=E13*0.6,"Ajustado","Reponer"))))
... A81: =IF(Maestro_SKU!A81="","",Maestro_SKU!A81) | B81: =IF(A81="","",IFERROR(VLOOKUP(A81,Maestro_SKU!$A$2:$P$500,2,FALSE),"")) | C81: =IF(A81="","",SUMIFS(Ventas_SellIn!$Y$2:$Y$800,Ventas_SellIn!$H$2:$H$800,A81,Ventas_SellIn!$B$2:$B$800,">="&TODAY()-cfg_VentanaDemanda)) | D81: =IF(A81="","",C81/cfg_VentanaDemanda) | E81: =IF(A81="","",ROUND(D81*cfg_DiasCobertura*(1+cfg_PctSeguridad),0)) | G81: =IF(A81="","",IF(F81="",0,F81*IFERROR(VLOOKUP(A81,Maestro_SKU!$A$2:$P$500,12,FALSE),1))) | H81: =IF(A81="","",MAX(E81-G81,0)) | I81: =IF(A81="","",IF(F81="","Falta bodega",IF(G81>=E81,"OK",IF(G81>=E81*0.6,"Ajustado","Reponer"))))

Sheet Cobertura
A1: PDV_ID | B1: Cliente | C1: Canal | D1: Punto de venta | E1: Frecuencia | F1: Última visita | G1: Días sin visita | H1: Estado visita | I1: Venta sell-in 30d neta | J1: Sell-out 30d unid. opcional | K1: Estado venta | L1: Facturas pendientes | M1: Monto pendiente | N1: Estado pago | O1: Stock PDV barras | P1: Estado stock | Q1: Prioridad lunes | R1: Acción sugerida | S1: Rotación | T1: ⚙ Configuración
A2: =IF(Clientes_PDV!A2="","",Clientes_PDV!A2) | B2: =IF(A2="","",IFERROR(VLOOKUP(A2,Clientes_PDV!$A$2:$J$250,2,FALSE),"")) | C2: =IF(A2="","",IFERROR(VLOOKUP(A2,Clientes_PDV!$A$2:$J$250,3,FALSE),"")) | D2: =IF(A2="","",IFERROR(VLOOKUP(A2,Clientes_PDV!$A$2:$J$250,4,FALSE),"")) | E2: =IF(A2="","",IFERROR(VLOOKUP(A2,Clientes_PDV!$A$2:$J$250,7,FALSE),"")) | F2: =IF(A2="","",IFERROR(VLOOKUP(A2,Clientes_PDV!$A$2:$J$250,8,FALSE),"")) | G2: =IF(F2="","",TODAY()-F2) | H2: =IF(A2="","",IF(F2="","Sin visita",IF(G2<=IFERROR(VLOOKUP(E2,Inicio!$A$24:$B$26,2,FALSE),0),"Vigente","Atrasado"))) | I2: =IF(A2="","",SUMIFS(Ventas_SellIn!$L$2:$L$800,Ventas_SellIn!$D$2:$D$800,A2,Ventas_SellIn!$B$2:$B$800,">="&TODAY()-Inicio!$B$14)) | J2: =IF(A2="","",SUMIFS(SellOut_Jumbo!$F$2:$F$800,SellOut_Jumbo!$C$2:$C$800,D2,SellOut_Jumbo!$A$2:$A$800,">="&TODAY()-Inicio!$B$14)) | K2: =IF(A2="","",IF(I2=0,"Sin venta",IF(I2<Inicio!$B$15,"Venta baja","Venta OK"))) | L2: =IF(A2="","",COUNTIFS(Ventas_SellIn!$D$2:$D$800,A2,Ventas_SellIn!$R$2:$R$800,">0")) | M2: =IF(A2="","",SUMIFS(Ventas_SellIn!$R$2:$R$800,Ventas_SellIn!$D$2:$D$800,A2)) | N2: =IF(A2="","",IF(M2>=Inicio!$B$18,"Pendiente relevante",IF(M2>0,"Pendiente menor","Sin deuda"))) | O2: =IF(A2="","",SUMIFS(Stock_PDV!$H$2:$H$800,Stock_PDV!$A$2:$A$800,A2)) | P2: =IF(A2="","",IF(O2<=Inicio!$B$16,"Crítico",IF(O2<=Inicio!$B$17,"Observar","OK"))) | Q2: =IF(A2="","",IF(OR(H2="Atrasado",K2="Sin venta",N2="Pendiente relevante",P2="Crítico"),"Alta",IF(OR(K2="Venta baja",N2="Pendiente menor",P2="Observar"),"Media","Baja"))) | R2: =IF(A2="","",IF(Q2="Alta","Gestionar esta semana",IF(Q2="Media","Hacer seguimiento","Mantener"))) | S2: =IF(A2="","",IF(I2=0,"Sin venta",IF(I2>=cfg_VentaAlta,"Alta",IF(I2<cfg_VentaBaja,"Baja","Media"))))
A3: =IF(Clientes_PDV!A3="","",Clientes_PDV!A3) | B3: =IF(A3="","",IFERROR(VLOOKUP(A3,Clientes_PDV!$A$2:$J$250,2,FALSE),"")) | C3: =IF(A3="","",IFERROR(VLOOKUP(A3,Clientes_PDV!$A$2:$J$250,3,FALSE),"")) | D3: =IF(A3="","",IFERROR(VLOOKUP(A3,Clientes_PDV!$A$2:$J$250,4,FALSE),"")) | E3: =IF(A3="","",IFERROR(VLOOKUP(A3,Clientes_PDV!$A$2:$J$250,7,FALSE),"")) | F3: =IF(A3="","",IFERROR(VLOOKUP(A3,Clientes_PDV!$A$2:$J$250,8,FALSE),"")) | G3: =IF(F3="","",TODAY()-F3) | H3: =IF(A3="","",IF(F3="","Sin visita",IF(G3<=IFERROR(VLOOKUP(E3,Inicio!$A$24:$B$26,2,FALSE),0),"Vigente","Atrasado"))) | I3: =IF(A3="","",SUMIFS(Ventas_SellIn!$L$2:$L$800,Ventas_SellIn!$D$2:$D$800,A3,Ventas_SellIn!$B$2:$B$800,">="&TODAY()-Inicio!$B$14)) | J3: =IF(A3="","",SUMIFS(SellOut_Jumbo!$F$2:$F$800,SellOut_Jumbo!$C$2:$C$800,D3,SellOut_Jumbo!$A$2:$A$800,">="&TODAY()-Inicio!$B$14)) | K3: =IF(A3="","",IF(I3=0,"Sin venta",IF(I3<Inicio!$B$15,"Venta baja","Venta OK"))) | L3: =IF(A3="","",COUNTIFS(Ventas_SellIn!$D$2:$D$800,A3,Ventas_SellIn!$R$2:$R$800,">0")) | M3: =IF(A3="","",SUMIFS(Ventas_SellIn!$R$2:$R$800,Ventas_SellIn!$D$2:$D$800,A3)) | N3: =IF(A3="","",IF(M3>=Inicio!$B$18,"Pendiente relevante",IF(M3>0,"Pendiente menor","Sin deuda"))) | O3: =IF(A3="","",SUMIFS(Stock_PDV!$H$2:$H$800,Stock_PDV!$A$2:$A$800,A3)) | P3: =IF(A3="","",IF(O3<=Inicio!$B$16,"Crítico",IF(O3<=Inicio!$B$17,"Observar","OK"))) | Q3: =IF(A3="","",IF(OR(H3="Atrasado",K3="Sin venta",N3="Pendiente relevante",P3="Crítico"),"Alta",IF(OR(K3="Venta baja",N3="Pendiente menor",P3="Observar"),"Media","Baja"))) | R3: =IF(A3="","",IF(Q3="Alta","Gestionar esta semana",IF(Q3="Media","Hacer seguimiento","Mantener"))) | S3: =IF(A3="","",IF(I3=0,"Sin venta",IF(I3>=cfg_VentaAlta,"Alta",IF(I3<cfg_VentaBaja,"Baja","Media"))))
A4: =IF(Clientes_PDV!A4="","",Clientes_PDV!A4) | B4: =IF(A4="","",IFERROR(VLOOKUP(A4,Clientes_PDV!$A$2:$J$250,2,FALSE),"")) | C4: =IF(A4="","",IFERROR(VLOOKUP(A4,Clientes_PDV!$A$2:$J$250,3,FALSE),"")) | D4: =IF(A4="","",IFERROR(VLOOKUP(A4,Clientes_PDV!$A$2:$J$250,4,FALSE),"")) | E4: =IF(A4="","",IFERROR(VLOOKUP(A4,Clientes_PDV!$A$2:$J$250,7,FALSE),"")) | F4: =IF(A4="","",IFERROR(VLOOKUP(A4,Clientes_PDV!$A$2:$J$250,8,FALSE),"")) | G4: =IF(F4="","",TODAY()-F4) | H4: =IF(A4="","",IF(F4="","Sin visita",IF(G4<=IFERROR(VLOOKUP(E4,Inicio!$A$24:$B$26,2,FALSE),0),"Vigente","Atrasado"))) | I4: =IF(A4="","",SUMIFS(Ventas_SellIn!$L$2:$L$800,Ventas_SellIn!$D$2:$D$800,A4,Ventas_SellIn!$B$2:$B$800,">="&TODAY()-Inicio!$B$14)) | J4: =IF(A4="","",SUMIFS(SellOut_Jumbo!$F$2:$F$800,SellOut_Jumbo!$C$2:$C$800,D4,SellOut_Jumbo!$A$2:$A$800,">="&TODAY()-Inicio!$B$14)) | K4: =IF(A4="","",IF(I4=0,"Sin venta",IF(I4<Inicio!$B$15,"Venta baja","Venta OK"))) | L4: =IF(A4="","",COUNTIFS(Ventas_SellIn!$D$2:$D$800,A4,Ventas_SellIn!$R$2:$R$800,">0")) | M4: =IF(A4="","",SUMIFS(Ventas_SellIn!$R$2:$R$800,Ventas_SellIn!$D$2:$D$800,A4)) | N4: =IF(A4="","",IF(M4>=Inicio!$B$18,"Pendiente relevante",IF(M4>0,"Pendiente menor","Sin deuda"))) | O4: =IF(A4="","",SUMIFS(Stock_PDV!$H$2:$H$800,Stock_PDV!$A$2:$A$800,A4)) | P4: =IF(A4="","",IF(O4<=Inicio!$B$16,"Crítico",IF(O4<=Inicio!$B$17,"Observar","OK"))) | Q4: =IF(A4="","",IF(OR(H4="Atrasado",K4="Sin venta",N4="Pendiente relevante",P4="Crítico"),"Alta",IF(OR(K4="Venta baja",N4="Pendiente menor",P4="Observar"),"Media","Baja"))) | R4: =IF(A4="","",IF(Q4="Alta","Gestionar esta semana",IF(Q4="Media","Hacer seguimiento","Mantener"))) | S4: =IF(A4="","",IF(I4=0,"Sin venta",IF(I4>=cfg_VentaAlta,"Alta",IF(I4<cfg_VentaBaja,"Baja","Media"))))
A5: =IF(Clientes_PDV!A5="","",Clientes_PDV!A5) | B5: =IF(A5="","",IFERROR(VLOOKUP(A5,Clientes_PDV!$A$2:$J$250,2,FALSE),"")) | C5: =IF(A5="","",IFERROR(VLOOKUP(A5,Clientes_PDV!$A$2:$J$250,3,FALSE),"")) | D5: =IF(A5="","",IFERROR(VLOOKUP(A5,Clientes_PDV!$A$2:$J$250,4,FALSE),"")) | E5: =IF(A5="","",IFERROR(VLOOKUP(A5,Clientes_PDV!$A$2:$J$250,7,FALSE),"")) | F5: =IF(A5="","",IFERROR(VLOOKUP(A5,Clientes_PDV!$A$2:$J$250,8,FALSE),"")) | G5: =IF(F5="","",TODAY()-F5) | H5: =IF(A5="","",IF(F5="","Sin visita",IF(G5<=IFERROR(VLOOKUP(E5,Inicio!$A$24:$B$26,2,FALSE),0),"Vigente","Atrasado"))) | I5: =IF(A5="","",SUMIFS(Ventas_SellIn!$L$2:$L$800,Ventas_SellIn!$D$2:$D$800,A5,Ventas_SellIn!$B$2:$B$800,">="&TODAY()-Inicio!$B$14)) | J5: =IF(A5="","",SUMIFS(SellOut_Jumbo!$F$2:$F$800,SellOut_Jumbo!$C$2:$C$800,D5,SellOut_Jumbo!$A$2:$A$800,">="&TODAY()-Inicio!$B$14)) | K5: =IF(A5="","",IF(I5=0,"Sin venta",IF(I5<Inicio!$B$15,"Venta baja","Venta OK"))) | L5: =IF(A5="","",COUNTIFS(Ventas_SellIn!$D$2:$D$800,A5,Ventas_SellIn!$R$2:$R$800,">0")) | M5: =IF(A5="","",SUMIFS(Ventas_SellIn!$R$2:$R$800,Ventas_SellIn!$D$2:$D$800,A5)) | N5: =IF(A5="","",IF(M5>=Inicio!$B$18,"Pendiente relevante",IF(M5>0,"Pendiente menor","Sin deuda"))) | O5: =IF(A5="","",SUMIFS(Stock_PDV!$H$2:$H$800,Stock_PDV!$A$2:$A$800,A5)) | P5: =IF(A5="","",IF(O5<=Inicio!$B$16,"Crítico",IF(O5<=Inicio!$B$17,"Observar","OK"))) | Q5: =IF(A5="","",IF(OR(H5="Atrasado",K5="Sin venta",N5="Pendiente relevante",P5="Crítico"),"Alta",IF(OR(K5="Venta baja",N5="Pendiente menor",P5="Observar"),"Media","Baja"))) | R5: =IF(A5="","",IF(Q5="Alta","Gestionar esta semana",IF(Q5="Media","Hacer seguimiento","Mantener"))) | S5: =IF(A5="","",IF(I5=0,"Sin venta",IF(I5>=cfg_VentaAlta,"Alta",IF(I5<cfg_VentaBaja,"Baja","Media"))))
A6: =IF(Clientes_PDV!A6="","",Clientes_PDV!A6) | B6: =IF(A6="","",IFERROR(VLOOKUP(A6,Clientes_PDV!$A$2:$J$250,2,FALSE),"")) | C6: =IF(A6="","",IFERROR(VLOOKUP(A6,Clientes_PDV!$A$2:$J$250,3,FALSE),"")) | D6: =IF(A6="","",IFERROR(VLOOKUP(A6,Clientes_PDV!$A$2:$J$250,4,FALSE),"")) | E6: =IF(A6="","",IFERROR(VLOOKUP(A6,Clientes_PDV!$A$2:$J$250,7,FALSE),"")) | F6: =IF(A6="","",IFERROR(VLOOKUP(A6,Clientes_PDV!$A$2:$J$250,8,FALSE),"")) | G6: =IF(F6="","",TODAY()-F6) | H6: =IF(A6="","",IF(F6="","Sin visita",IF(G6<=IFERROR(VLOOKUP(E6,Inicio!$A$24:$B$26,2,FALSE),0),"Vigente","Atrasado"))) | I6: =IF(A6="","",SUMIFS(Ventas_SellIn!$L$2:$L$800,Ventas_SellIn!$D$2:$D$800,A6,Ventas_SellIn!$B$2:$B$800,">="&TODAY()-Inicio!$B$14)) | J6: =IF(A6="","",SUMIFS(SellOut_Jumbo!$F$2:$F$800,SellOut_Jumbo!$C$2:$C$800,D6,SellOut_Jumbo!$A$2:$A$800,">="&TODAY()-Inicio!$B$14)) | K6: =IF(A6="","",IF(I6=0,"Sin venta",IF(I6<Inicio!$B$15,"Venta baja","Venta OK"))) | L6: =IF(A6="","",COUNTIFS(Ventas_SellIn!$D$2:$D$800,A6,Ventas_SellIn!$R$2:$R$800,">0")) | M6: =IF(A6="","",SUMIFS(Ventas_SellIn!$R$2:$R$800,Ventas_SellIn!$D$2:$D$800,A6)) | N6: =IF(A6="","",IF(M6>=Inicio!$B$18,"Pendiente relevante",IF(M6>0,"Pendiente menor","Sin deuda"))) | O6: =IF(A6="","",SUMIFS(Stock_PDV!$H$2:$H$800,Stock_PDV!$A$2:$A$800,A6)) | P6: =IF(A6="","",IF(O6<=Inicio!$B$16,"Crítico",IF(O6<=Inicio!$B$17,"Observar","OK"))) | Q6: =IF(A6="","",IF(OR(H6="Atrasado",K6="Sin venta",N6="Pendiente relevante",P6="Crítico"),"Alta",IF(OR(K6="Venta baja",N6="Pendiente menor",P6="Observar"),"Media","Baja"))) | R6: =IF(A6="","",IF(Q6="Alta","Gestionar esta semana",IF(Q6="Media","Hacer seguimiento","Mantener"))) | S6: =IF(A6="","",IF(I6=0,"Sin venta",IF(I6>=cfg_VentaAlta,"Alta",IF(I6<cfg_VentaBaja,"Baja","Media"))))
A7: =IF(Clientes_PDV!A7="","",Clientes_PDV!A7) | B7: =IF(A7="","",IFERROR(VLOOKUP(A7,Clientes_PDV!$A$2:$J$250,2,FALSE),"")) | C7: =IF(A7="","",IFERROR(VLOOKUP(A7,Clientes_PDV!$A$2:$J$250,3,FALSE),"")) | D7: =IF(A7="","",IFERROR(VLOOKUP(A7,Clientes_PDV!$A$2:$J$250,4,FALSE),"")) | E7: =IF(A7="","",IFERROR(VLOOKUP(A7,Clientes_PDV!$A$2:$J$250,7,FALSE),"")) | F7: =IF(A7="","",IFERROR(VLOOKUP(A7,Clientes_PDV!$A$2:$J$250,8,FALSE),"")) | G7: =IF(F7="","",TODAY()-F7) | H7: =IF(A7="","",IF(F7="","Sin visita",IF(G7<=IFERROR(VLOOKUP(E7,Inicio!$A$24:$B$26,2,FALSE),0),"Vigente","Atrasado"))) | I7: =IF(A7="","",SUMIFS(Ventas_SellIn!$L$2:$L$800,Ventas_SellIn!$D$2:$D$800,A7,Ventas_SellIn!$B$2:$B$800,">="&TODAY()-Inicio!$B$14)) | J7: =IF(A7="","",SUMIFS(SellOut_Jumbo!$F$2:$F$800,SellOut_Jumbo!$C$2:$C$800,D7,SellOut_Jumbo!$A$2:$A$800,">="&TODAY()-Inicio!$B$14)) | K7: =IF(A7="","",IF(I7=0,"Sin venta",IF(I7<Inicio!$B$15,"Venta baja","Venta OK"))) | L7: =IF(A7="","",COUNTIFS(Ventas_SellIn!$D$2:$D$800,A7,Ventas_SellIn!$R$2:$R$800,">0")) | M7: =IF(A7="","",SUMIFS(Ventas_SellIn!$R$2:$R$800,Ventas_SellIn!$D$2:$D$800,A7)) | N7: =IF(A7="","",IF(M7>=Inicio!$B$18,"Pendiente relevante",IF(M7>0,"Pendiente menor","Sin deuda"))) | O7: =IF(A7="","",SUMIFS(Stock_PDV!$H$2:$H$800,Stock_PDV!$A$2:$A$800,A7)) | P7: =IF(A7="","",IF(O7<=Inicio!$B$16,"Crítico",IF(O7<=Inicio!$B$17,"Observar","OK"))) | Q7: =IF(A7="","",IF(OR(H7="Atrasado",K7="Sin venta",N7="Pendiente relevante",P7="Crítico"),"Alta",IF(OR(K7="Venta baja",N7="Pendiente menor",P7="Observar"),"Media","Baja"))) | R7: =IF(A7="","",IF(Q7="Alta","Gestionar esta semana",IF(Q7="Media","Hacer seguimiento","Mantener"))) | S7: =IF(A7="","",IF(I7=0,"Sin venta",IF(I7>=cfg_VentaAlta,"Alta",IF(I7<cfg_VentaBaja,"Baja","Media"))))
A8: =IF(Clientes_PDV!A8="","",Clientes_PDV!A8) | B8: =IF(A8="","",IFERROR(VLOOKUP(A8,Clientes_PDV!$A$2:$J$250,2,FALSE),"")) | C8: =IF(A8="","",IFERROR(VLOOKUP(A8,Clientes_PDV!$A$2:$J$250,3,FALSE),"")) | D8: =IF(A8="","",IFERROR(VLOOKUP(A8,Clientes_PDV!$A$2:$J$250,4,FALSE),"")) | E8: =IF(A8="","",IFERROR(VLOOKUP(A8,Clientes_PDV!$A$2:$J$250,7,FALSE),"")) | F8: =IF(A8="","",IFERROR(VLOOKUP(A8,Clientes_PDV!$A$2:$J$250,8,FALSE),"")) | G8: =IF(F8="","",TODAY()-F8) | H8: =IF(A8="","",IF(F8="","Sin visita",IF(G8<=IFERROR(VLOOKUP(E8,Inicio!$A$24:$B$26,2,FALSE),0),"Vigente","Atrasado"))) | I8: =IF(A8="","",SUMIFS(Ventas_SellIn!$L$2:$L$800,Ventas_SellIn!$D$2:$D$800,A8,Ventas_SellIn!$B$2:$B$800,">="&TODAY()-Inicio!$B$14)) | J8: =IF(A8="","",SUMIFS(SellOut_Jumbo!$F$2:$F$800,SellOut_Jumbo!$C$2:$C$800,D8,SellOut_Jumbo!$A$2:$A$800,">="&TODAY()-Inicio!$B$14)) | K8: =IF(A8="","",IF(I8=0,"Sin venta",IF(I8<Inicio!$B$15,"Venta baja","Venta OK"))) | L8: =IF(A8="","",COUNTIFS(Ventas_SellIn!$D$2:$D$800,A8,Ventas_SellIn!$R$2:$R$800,">0")) | M8: =IF(A8="","",SUMIFS(Ventas_SellIn!$R$2:$R$800,Ventas_SellIn!$D$2:$D$800,A8)) | N8: =IF(A8="","",IF(M8>=Inicio!$B$18,"Pendiente relevante",IF(M8>0,"Pendiente menor","Sin deuda"))) | O8: =IF(A8="","",SUMIFS(Stock_PDV!$H$2:$H$800,Stock_PDV!$A$2:$A$800,A8)) | P8: =IF(A8="","",IF(O8<=Inicio!$B$16,"Crítico",IF(O8<=Inicio!$B$17,"Observar","OK"))) | Q8: =IF(A8="","",IF(OR(H8="Atrasado",K8="Sin venta",N8="Pendiente relevante",P8="Crítico"),"Alta",IF(OR(K8="Venta baja",N8="Pendiente menor",P8="Observar"),"Media","Baja"))) | R8: =IF(A8="","",IF(Q8="Alta","Gestionar esta semana",IF(Q8="Media","Hacer seguimiento","Mantener"))) | S8: =IF(A8="","",IF(I8=0,"Sin venta",IF(I8>=cfg_VentaAlta,"Alta",IF(I8<cfg_VentaBaja,"Baja","Media"))))
A9: =IF(Clientes_PDV!A9="","",Clientes_PDV!A9) | B9: =IF(A9="","",IFERROR(VLOOKUP(A9,Clientes_PDV!$A$2:$J$250,2,FALSE),"")) | C9: =IF(A9="","",IFERROR(VLOOKUP(A9,Clientes_PDV!$A$2:$J$250,3,FALSE),"")) | D9: =IF(A9="","",IFERROR(VLOOKUP(A9,Clientes_PDV!$A$2:$J$250,4,FALSE),"")) | E9: =IF(A9="","",IFERROR(VLOOKUP(A9,Clientes_PDV!$A$2:$J$250,7,FALSE),"")) | F9: =IF(A9="","",IFERROR(VLOOKUP(A9,Clientes_PDV!$A$2:$J$250,8,FALSE),"")) | G9: =IF(F9="","",TODAY()-F9) | H9: =IF(A9="","",IF(F9="","Sin visita",IF(G9<=IFERROR(VLOOKUP(E9,Inicio!$A$24:$B$26,2,FALSE),0),"Vigente","Atrasado"))) | I9: =IF(A9="","",SUMIFS(Ventas_SellIn!$L$2:$L$800,Ventas_SellIn!$D$2:$D$800,A9,Ventas_SellIn!$B$2:$B$800,">="&TODAY()-Inicio!$B$14)) | J9: =IF(A9="","",SUMIFS(SellOut_Jumbo!$F$2:$F$800,SellOut_Jumbo!$C$2:$C$800,D9,SellOut_Jumbo!$A$2:$A$800,">="&TODAY()-Inicio!$B$14)) | K9: =IF(A9="","",IF(I9=0,"Sin venta",IF(I9<Inicio!$B$15,"Venta baja","Venta OK"))) | L9: =IF(A9="","",COUNTIFS(Ventas_SellIn!$D$2:$D$800,A9,Ventas_SellIn!$R$2:$R$800,">0")) | M9: =IF(A9="","",SUMIFS(Ventas_SellIn!$R$2:$R$800,Ventas_SellIn!$D$2:$D$800,A9)) | N9: =IF(A9="","",IF(M9>=Inicio!$B$18,"Pendiente relevante",IF(M9>0,"Pendiente menor","Sin deuda"))) | O9: =IF(A9="","",SUMIFS(Stock_PDV!$H$2:$H$800,Stock_PDV!$A$2:$A$800,A9)) | P9: =IF(A9="","",IF(O9<=Inicio!$B$16,"Crítico",IF(O9<=Inicio!$B$17,"Observar","OK"))) | Q9: =IF(A9="","",IF(OR(H9="Atrasado",K9="Sin venta",N9="Pendiente relevante",P9="Crítico"),"Alta",IF(OR(K9="Venta baja",N9="Pendiente menor",P9="Observar"),"Media","Baja"))) | R9: =IF(A9="","",IF(Q9="Alta","Gestionar esta semana",IF(Q9="Media","Hacer seguimiento","Mantener"))) | S9: =IF(A9="","",IF(I9=0,"Sin venta",IF(I9>=cfg_VentaAlta,"Alta",IF(I9<cfg_VentaBaja,"Baja","Media"))))
A10: =IF(Clientes_PDV!A10="","",Clientes_PDV!A10) | B10: =IF(A10="","",IFERROR(VLOOKUP(A10,Clientes_PDV!$A$2:$J$250,2,FALSE),"")) | C10: =IF(A10="","",IFERROR(VLOOKUP(A10,Clientes_PDV!$A$2:$J$250,3,FALSE),"")) | D10: =IF(A10="","",IFERROR(VLOOKUP(A10,Clientes_PDV!$A$2:$J$250,4,FALSE),"")) | E10: =IF(A10="","",IFERROR(VLOOKUP(A10,Clientes_PDV!$A$2:$J$250,7,FALSE),"")) | F10: =IF(A10="","",IFERROR(VLOOKUP(A10,Clientes_PDV!$A$2:$J$250,8,FALSE),"")) | G10: =IF(F10="","",TODAY()-F10) | H10: =IF(A10="","",IF(F10="","Sin visita",IF(G10<=IFERROR(VLOOKUP(E10,Inicio!$A$24:$B$26,2,FALSE),0),"Vigente","Atrasado"))) | I10: =IF(A10="","",SUMIFS(Ventas_SellIn!$L$2:$L$800,Ventas_SellIn!$D$2:$D$800,A10,Ventas_SellIn!$B$2:$B$800,">="&TODAY()-Inicio!$B$14)) | J10: =IF(A10="","",SUMIFS(SellOut_Jumbo!$F$2:$F$800,SellOut_Jumbo!$C$2:$C$800,D10,SellOut_Jumbo!$A$2:$A$800,">="&TODAY()-Inicio!$B$14)) | K10: =IF(A10="","",IF(I10=0,"Sin venta",IF(I10<Inicio!$B$15,"Venta baja","Venta OK"))) | L10: =IF(A10="","",COUNTIFS(Ventas_SellIn!$D$2:$D$800,A10,Ventas_SellIn!$R$2:$R$800,">0")) | M10: =IF(A10="","",SUMIFS(Ventas_SellIn!$R$2:$R$800,Ventas_SellIn!$D$2:$D$800,A10)) | N10: =IF(A10="","",IF(M10>=Inicio!$B$18,"Pendiente relevante",IF(M10>0,"Pendiente menor","Sin deuda"))) | O10: =IF(A10="","",SUMIFS(Stock_PDV!$H$2:$H$800,Stock_PDV!$A$2:$A$800,A10)) | P10: =IF(A10="","",IF(O10<=Inicio!$B$16,"Crítico",IF(O10<=Inicio!$B$17,"Observar","OK"))) | Q10: =IF(A10="","",IF(OR(H10="Atrasado",K10="Sin venta",N10="Pendiente relevante",P10="Crítico"),"Alta",IF(OR(K10="Venta baja",N10="Pendiente menor",P10="Observar"),"Media","Baja"))) | R10: =IF(A10="","",IF(Q10="Alta","Gestionar esta semana",IF(Q10="Media","Hacer seguimiento","Mantener"))) | S10: =IF(A10="","",IF(I10=0,"Sin venta",IF(I10>=cfg_VentaAlta,"Alta",IF(I10<cfg_VentaBaja,"Baja","Media"))))
A11: =IF(Clientes_PDV!A11="","",Clientes_PDV!A11) | B11: =IF(A11="","",IFERROR(VLOOKUP(A11,Clientes_PDV!$A$2:$J$250,2,FALSE),"")) | C11: =IF(A11="","",IFERROR(VLOOKUP(A11,Clientes_PDV!$A$2:$J$250,3,FALSE),"")) | D11: =IF(A11="","",IFERROR(VLOOKUP(A11,Clientes_PDV!$A$2:$J$250,4,FALSE),"")) | E11: =IF(A11="","",IFERROR(VLOOKUP(A11,Clientes_PDV!$A$2:$J$250,7,FALSE),"")) | F11: =IF(A11="","",IFERROR(VLOOKUP(A11,Clientes_PDV!$A$2:$J$250,8,FALSE),"")) | G11: =IF(F11="","",TODAY()-F11) | H11: =IF(A11="","",IF(F11="","Sin visita",IF(G11<=IFERROR(VLOOKUP(E11,Inicio!$A$24:$B$26,2,FALSE),0),"Vigente","Atrasado"))) | I11: =IF(A11="","",SUMIFS(Ventas_SellIn!$L$2:$L$800,Ventas_SellIn!$D$2:$D$800,A11,Ventas_SellIn!$B$2:$B$800,">="&TODAY()-Inicio!$B$14)) | J11: =IF(A11="","",SUMIFS(SellOut_Jumbo!$F$2:$F$800,SellOut_Jumbo!$C$2:$C$800,D11,SellOut_Jumbo!$A$2:$A$800,">="&TODAY()-Inicio!$B$14)) | K11: =IF(A11="","",IF(I11=0,"Sin venta",IF(I11<Inicio!$B$15,"Venta baja","Venta OK"))) | L11: =IF(A11="","",COUNTIFS(Ventas_SellIn!$D$2:$D$800,A11,Ventas_SellIn!$R$2:$R$800,">0")) | M11: =IF(A11="","",SUMIFS(Ventas_SellIn!$R$2:$R$800,Ventas_SellIn!$D$2:$D$800,A11)) | N11: =IF(A11="","",IF(M11>=Inicio!$B$18,"Pendiente relevante",IF(M11>0,"Pendiente menor","Sin deuda"))) | O11: =IF(A11="","",SUMIFS(Stock_PDV!$H$2:$H$800,Stock_PDV!$A$2:$A$800,A11)) | P11: =IF(A11="","",IF(O11<=Inicio!$B$16,"Crítico",IF(O11<=Inicio!$B$17,"Observar","OK"))) | Q11: =IF(A11="","",IF(OR(H11="Atrasado",K11="Sin venta",N11="Pendiente relevante",P11="Crítico"),"Alta",IF(OR(K11="Venta baja",N11="Pendiente menor",P11="Observar"),"Media","Baja"))) | R11: =IF(A11="","",IF(Q11="Alta","Gestionar esta semana",IF(Q11="Media","Hacer seguimiento","Mantener"))) | S11: =IF(A11="","",IF(I11=0,"Sin venta",IF(I11>=cfg_VentaAlta,"Alta",IF(I11<cfg_VentaBaja,"Baja","Media"))))
A12: =IF(Clientes_PDV!A12="","",Clientes_PDV!A12) | B12: =IF(A12="","",IFERROR(VLOOKUP(A12,Clientes_PDV!$A$2:$J$250,2,FALSE),"")) | C12: =IF(A12="","",IFERROR(VLOOKUP(A12,Clientes_PDV!$A$2:$J$250,3,FALSE),"")) | D12: =IF(A12="","",IFERROR(VLOOKUP(A12,Clientes_PDV!$A$2:$J$250,4,FALSE),"")) | E12: =IF(A12="","",IFERROR(VLOOKUP(A12,Clientes_PDV!$A$2:$J$250,7,FALSE),"")) | F12: =IF(A12="","",IFERROR(VLOOKUP(A12,Clientes_PDV!$A$2:$J$250,8,FALSE),"")) | G12: =IF(F12="","",TODAY()-F12) | H12: =IF(A12="","",IF(F12="","Sin visita",IF(G12<=IFERROR(VLOOKUP(E12,Inicio!$A$24:$B$26,2,FALSE),0),"Vigente","Atrasado"))) | I12: =IF(A12="","",SUMIFS(Ventas_SellIn!$L$2:$L$800,Ventas_SellIn!$D$2:$D$800,A12,Ventas_SellIn!$B$2:$B$800,">="&TODAY()-Inicio!$B$14)) | J12: =IF(A12="","",SUMIFS(SellOut_Jumbo!$F$2:$F$800,SellOut_Jumbo!$C$2:$C$800,D12,SellOut_Jumbo!$A$2:$A$800,">="&TODAY()-Inicio!$B$14)) | K12: =IF(A12="","",IF(I12=0,"Sin venta",IF(I12<Inicio!$B$15,"Venta baja","Venta OK"))) | L12: =IF(A12="","",COUNTIFS(Ventas_SellIn!$D$2:$D$800,A12,Ventas_SellIn!$R$2:$R$800,">0")) | M12: =IF(A12="","",SUMIFS(Ventas_SellIn!$R$2:$R$800,Ventas_SellIn!$D$2:$D$800,A12)) | N12: =IF(A12="","",IF(M12>=Inicio!$B$18,"Pendiente relevante",IF(M12>0,"Pendiente menor","Sin deuda"))) | O12: =IF(A12="","",SUMIFS(Stock_PDV!$H$2:$H$800,Stock_PDV!$A$2:$A$800,A12)) | P12: =IF(A12="","",IF(O12<=Inicio!$B$16,"Crítico",IF(O12<=Inicio!$B$17,"Observar","OK"))) | Q12: =IF(A12="","",IF(OR(H12="Atrasado",K12="Sin venta",N12="Pendiente relevante",P12="Crítico"),"Alta",IF(OR(K12="Venta baja",N12="Pendiente menor",P12="Observar"),"Media","Baja"))) | R12: =IF(A12="","",IF(Q12="Alta","Gestionar esta semana",IF(Q12="Media","Hacer seguimiento","Mantener"))) | S12: =IF(A12="","",IF(I12=0,"Sin venta",IF(I12>=cfg_VentaAlta,"Alta",IF(I12<cfg_VentaBaja,"Baja","Media"))))
A13: =IF(Clientes_PDV!A13="","",Clientes_PDV!A13) | B13: =IF(A13="","",IFERROR(VLOOKUP(A13,Clientes_PDV!$A$2:$J$250,2,FALSE),"")) | C13: =IF(A13="","",IFERROR(VLOOKUP(A13,Clientes_PDV!$A$2:$J$250,3,FALSE),"")) | D13: =IF(A13="","",IFERROR(VLOOKUP(A13,Clientes_PDV!$A$2:$J$250,4,FALSE),"")) | E13: =IF(A13="","",IFERROR(VLOOKUP(A13,Clientes_PDV!$A$2:$J$250,7,FALSE),"")) | F13: =IF(A13="","",IFERROR(VLOOKUP(A13,Clientes_PDV!$A$2:$J$250,8,FALSE),"")) | G13: =IF(F13="","",TODAY()-F13) | H13: =IF(A13="","",IF(F13="","Sin visita",IF(G13<=IFERROR(VLOOKUP(E13,Inicio!$A$24:$B$26,2,FALSE),0),"Vigente","Atrasado"))) | I13: =IF(A13="","",SUMIFS(Ventas_SellIn!$L$2:$L$800,Ventas_SellIn!$D$2:$D$800,A13,Ventas_SellIn!$B$2:$B$800,">="&TODAY()-Inicio!$B$14)) | J13: =IF(A13="","",SUMIFS(SellOut_Jumbo!$F$2:$F$800,SellOut_Jumbo!$C$2:$C$800,D13,SellOut_Jumbo!$A$2:$A$800,">="&TODAY()-Inicio!$B$14)) | K13: =IF(A13="","",IF(I13=0,"Sin venta",IF(I13<Inicio!$B$15,"Venta baja","Venta OK"))) | L13: =IF(A13="","",COUNTIFS(Ventas_SellIn!$D$2:$D$800,A13,Ventas_SellIn!$R$2:$R$800,">0")) | M13: =IF(A13="","",SUMIFS(Ventas_SellIn!$R$2:$R$800,Ventas_SellIn!$D$2:$D$800,A13)) | N13: =IF(A13="","",IF(M13>=Inicio!$B$18,"Pendiente relevante",IF(M13>0,"Pendiente menor","Sin deuda"))) | O13: =IF(A13="","",SUMIFS(Stock_PDV!$H$2:$H$800,Stock_PDV!$A$2:$A$800,A13)) | P13: =IF(A13="","",IF(O13<=Inicio!$B$16,"Crítico",IF(O13<=Inicio!$B$17,"Observar","OK"))) | Q13: =IF(A13="","",IF(OR(H13="Atrasado",K13="Sin venta",N13="Pendiente relevante",P13="Crítico"),"Alta",IF(OR(K13="Venta baja",N13="Pendiente menor",P13="Observar"),"Media","Baja"))) | R13: =IF(A13="","",IF(Q13="Alta","Gestionar esta semana",IF(Q13="Media","Hacer seguimiento","Mantener"))) | S13: =IF(A13="","",IF(I13=0,"Sin venta",IF(I13>=cfg_VentaAlta,"Alta",IF(I13<cfg_VentaBaja,"Baja","Media"))))
... A250: =IF(Clientes_PDV!A250="","",Clientes_PDV!A250) | B250: =IF(A250="","",IFERROR(VLOOKUP(A250,Clientes_PDV!$A$2:$J$250,2,FALSE),"")) | C250: =IF(A250="","",IFERROR(VLOOKUP(A250,Clientes_PDV!$A$2:$J$250,3,FALSE),"")) | D250: =IF(A250="","",IFERROR(VLOOKUP(A250,Clientes_PDV!$A$2:$J$250,4,FALSE),"")) | E250: =IF(A250="","",IFERROR(VLOOKUP(A250,Clientes_PDV!$A$2:$J$250,7,FALSE),"")) | F250: =IF(A250="","",IFERROR(VLOOKUP(A250,Clientes_PDV!$A$2:$J$250,8,FALSE),"")) | G250: =IF(F250="","",TODAY()-F250) | H250: =IF(A250="","",IF(F250="","Sin visita",IF(G250<=IFERROR(VLOOKUP(E250,Inicio!$A$24:$B$26,2,FALSE),0),"Vigente","Atrasado"))) | I250: =IF(A250="","",SUMIFS(Ventas_SellIn!$L$2:$L$800,Ventas_SellIn!$D$2:$D$800,A250,Ventas_SellIn!$B$2:$B$800,">="&TODAY()-Inicio!$B$14)) | J250: =IF(A250="","",SUMIFS(SellOut_Jumbo!$F$2:$F$800,SellOut_Jumbo!$C$2:$C$800,D250,SellOut_Jumbo!$A$2:$A$800,">="&TODAY()-Inicio!$B$14)) | K250: =IF(A250="","",IF(I250=0,"Sin venta",IF(I250<Inicio!$B$15,"Venta baja","Venta OK"))) | L250: =IF(A250="","",COUNTIFS(Ventas_SellIn!$D$2:$D$800,A250,Ventas_SellIn!$R$2:$R$800,">0")) | M250: =IF(A250="","",SUMIFS(Ventas_SellIn!$R$2:$R$800,Ventas_SellIn!$D$2:$D$800,A250)) | N250: =IF(A250="","",IF(M250>=Inicio!$B$18,"Pendiente relevante",IF(M250>0,"Pendiente menor","Sin deuda"))) | O250: =IF(A250="","",SUMIFS(Stock_PDV!$H$2:$H$800,Stock_PDV!$A$2:$A$800,A250)) | P250: =IF(A250="","",IF(O250<=Inicio!$B$16,"Crítico",IF(O250<=Inicio!$B$17,"Observar","OK"))) | Q250: =IF(A250="","",IF(OR(H250="Atrasado",K250="Sin venta",N250="Pendiente relevante",P250="Crítico"),"Alta",IF(OR(K250="Venta baja",N250="Pendiente menor",P250="Observar"),"Media","Baja"))) | R250: =IF(A250="","",IF(Q250="Alta","Gestionar esta semana",IF(Q250="Media","Hacer seguimiento","Mantener"))) | S250: =IF(A250="","",IF(I250=0,"Sin venta",IF(I250>=cfg_VentaAlta,"Alta",IF(I250<cfg_VentaBaja,"Baja","Media"))))

Sheet Clientes_PDV
A1: PDV_ID | B1: Cliente | C1: Canal | D1: Punto de venta | E1: Comuna | F1: Región | G1: Frecuencia visita | H1: Última visita | I1: Estado cliente | J1: Observaciones | L1: ⚙ Configuración
A2: PDV-001 | B2: Jumbo | C2: Retail | D2: Jumbo Bilbao | E2: Las Condes | F2: RM | G2: Semanal | H2: 46209 | I2: Activo | J2: Sala prioritaria
A3: PDV-002 | B3: Jumbo | C3: Retail | D3: Jumbo Kennedy | E3: Vitacura | F3: RM | G3: Semanal | H3: 46201 | I3: Activo | J3: Revisar reposición
A4: PDV-003 | B4: Jumbo | C4: Retail | D4: Jumbo La Reina | E4: La Reina | F4: RM | G4: Quincenal | H4: 46197 | I4: Activo
A5: PDV-004 | B5: Get It | C5: Conveniencia | D5: Get It Apoquindo | E5: Las Condes | F5: RM | G5: Semanal | H5: 46206 | I5: Activo
A6: PDV-005 | B6: Get It | C6: Conveniencia | D6: Get It Vitacura | E6: Vitacura | F6: RM | G6: Quincenal | H6: 46191 | I6: Activo
A7: PDV-006 | B7: Aldea Nativa | C7: Especializadas | D7: Aldea Nativa Providencia | E7: Providencia | F7: RM | G7: Mensual | H7: 46182 | I7: Activo
A8: PDV-007 | B8: All Nutrition | C8: Especializadas | D8: All Nutrition La Reina | E8: La Reina | F8: RM | G8: Mensual | H8: 46167 | I8: Activo | J8: Sin venta reciente
A9: PDV-008 | B9: Farmacia Ahumada | C9: Farmacias | D9: Ahumada Los Dominicos | E9: Las Condes | F9: RM | G9: Quincenal | H9: 46203 | I9: Prospecto
A10: PDV-009 | B10: Cruz Verde | C10: Farmacias | D10: Cruz Verde Vitacura | E10: Vitacura | F10: RM | G10: Quincenal | H10: 46194 | I10: Activo
A11: PDV-010 | B11: Sodexo | C11: Corporativo | D11: Sodexo Casa Matriz | E11: Providencia | F11: RM | G11: Mensual | H11: 46185 | I11: Activo
A12: PDV-011 | B12: Tres Toques | C12: HORECA | D12: Tres Toques Vitacura | E12: Vitacura | F12: RM | G12: Mensual | H12: 46204 | I12: Activo
A13: PDV-012 | B13: Mundo del Vino | C13: Especializadas | D13: Mundo del Vino Escuela Militar | E13: Las Condes | F13: RM | G13: Quincenal | H13: 46207 | I13: Activo

Sheet Ventas_SellIn
A1: ID_venta | B1: Fecha factura | C1: N° factura | D1: PDV_ID | E1: Cliente | F1: Canal | G1: Punto de venta | H1: SKU | I1: Descripción SKU | J1: Cantidad facturada | K1: Precio neto unit. facturado | L1: Venta neta | M1: IVA | N1: Venta bruta | O1: Fecha vencimiento | P1: Status pago | Q1: Monto pagado | R1: Monto pendiente | S1: Estado factura | T1: Observaciones | U1: Año | V1: Mes | W1: Día | X1: Periodo | Y1: Barras equiv | Z1: ⚙ Configuración
A2: V-0001 | B2: 46199 | C2: F-202607001 | D2: PDV-010 | E2: =IFERROR(VLOOKUP(D2,Clientes_PDV!$A$2:$J$250,2,FALSE),"") | F2: =IFERROR(VLOOKUP(D2,Clientes_PDV!$A$2:$J$250,3,FALSE),"") | G2: =IFERROR(VLOOKUP(D2,Clientes_PDV!$A$2:$J$250,4,FALSE),"") | H2: NUVA-BAR-BM-U-01 | I2: =IFERROR(VLOOKUP(H2,Maestro_SKU!$A$2:$P$500,2,FALSE),"") | J2: 20 | K2: 911 | L2: =IF(OR(J2="",K2=""),"",J2*K2) | M2: =IF(L2="","",L2*Inicio!$B$13) | N2: =IF(L2="","",L2+M2) | O2: 46244 | P2: Parcial | Q2: 14349 | R2: =IF(N2="","",MAX(N2-Q2,0)) | S2: =IF(A2="","",IF(OR(P2="Pagada",R2=0),"Pagada",IF(O2<TODAY(),"Vencida",IF(O2<=TODAY()+Inicio!$B$19,"Próxima a vencer","Vigente")))) | U2: =IF($B2="","",YEAR($B2)) | V2: =IF($B2="","",MONTH($B2)) | W2: =IF($B2="","",DAY($B2)) | X2: =IF($B2="","",YEAR($B2)&"-"&TEXT(MONTH($B2),"00")) | Y2: =IF(OR($H2="",$J2=""),"",$J2*IFERROR(VLOOKUP($H2,Maestro_SKU!$A$2:$P$500,12,FALSE),1))
A3: V-0002 | B3: 46208 | C3: F-202607002 | D3: PDV-011 | E3: =IFERROR(VLOOKUP(D3,Clientes_PDV!$A$2:$J$250,2,FALSE),"") | F3: =IFERROR(VLOOKUP(D3,Clientes_PDV!$A$2:$J$250,3,FALSE),"") | G3: =IFERROR(VLOOKUP(D3,Clientes_PDV!$A$2:$J$250,4,FALSE),"") | H3: NUVA-BAR-CC-U-01 | I3: =IFERROR(VLOOKUP(H3,Maestro_SKU!$A$2:$P$500,2,FALSE),"") | J3: 4 | K3: 948 | L3: =IF(OR(J3="",K3=""),"",J3*K3) | M3: =IF(L3="","",L3*Inicio!$B$13) | N3: =IF(L3="","",L3+M3) | O3: 46223 | P3: Vencida | Q3: 0 | R3: =IF(N3="","",MAX(N3-Q3,0)) | S3: =IF(A3="","",IF(OR(P3="Pagada",R3=0),"Pagada",IF(O3<TODAY(),"Vencida",IF(O3<=TODAY()+Inicio!$B$19,"Próxima a vencer","Vigente")))) | U3: =IF($B3="","",YEAR($B3)) | V3: =IF($B3="","",MONTH($B3)) | W3: =IF($B3="","",DAY($B3)) | X3: =IF($B3="","",YEAR($B3)&"-"&TEXT(MONTH($B3),"00")) | Y3: =IF(OR($H3="",$J3=""),"",$J3*IFERROR(VLOOKUP($H3,Maestro_SKU!$A$2:$P$500,12,FALSE),1))
A4: V-0003 | B4: 46174 | C4: F-202607003 | D4: PDV-012 | E4: =IFERROR(VLOOKUP(D4,Clientes_PDV!$A$2:$J$250,2,FALSE),"") | F4: =IFERROR(VLOOKUP(D4,Clientes_PDV!$A$2:$J$250,3,FALSE),"") | G4: =IFERROR(VLOOKUP(D4,Clientes_PDV!$A$2:$J$250,4,FALSE),"") | H4: NUVA-BAR-CC-BX-04 | I4: =IFERROR(VLOOKUP(H4,Maestro_SKU!$A$2:$P$500,2,FALSE),"") | J4: 4 | K4: 3807 | L4: =IF(OR(J4="",K4=""),"",J4*K4) | M4: =IF(L4="","",L4*Inicio!$B$13) | N4: =IF(L4="","",L4+M4) | O4: 46204 | P4: Pagada | Q4: 18121.32 | R4: =IF(N4="","",MAX(N4-Q4,0)) | S4: =IF(A4="","",IF(OR(P4="Pagada",R4=0),"Pagada",IF(O4<TODAY(),"Vencida",IF(O4<=TODAY()+Inicio!$B$19,"Próxima a vencer","Vigente")))) | U4: =IF($B4="","",YEAR($B4)) | V4: =IF($B4="","",MONTH($B4)) | W4: =IF($B4="","",DAY($B4)) | X4: =IF($B4="","",YEAR($B4)&"-"&TEXT(MONTH($B4),"00")) | Y4: =IF(OR($H4="",$J4=""),"",$J4*IFERROR(VLOOKUP($H4,Maestro_SKU!$A$2:$P$500,12,FALSE),1))
A5: V-0004 | B5: 46170 | C5: F-202607004 | D5: PDV-005 | E5: =IFERROR(VLOOKUP(D5,Clientes_PDV!$A$2:$J$250,2,FALSE),"") | F5: =IFERROR(VLOOKUP(D5,Clientes_PDV!$A$2:$J$250,3,FALSE),"") | G5: =IFERROR(VLOOKUP(D5,Clientes_PDV!$A$2:$J$250,4,FALSE),"") | H5: NUVA-BAR-PB-BX-04 | I5: =IFERROR(VLOOKUP(H5,Maestro_SKU!$A$2:$P$500,2,FALSE),"") | J5: 24 | K5: 3130 | L5: =IF(OR(J5="",K5=""),"",J5*K5) | M5: =IF(L5="","",L5*Inicio!$B$13) | N5: =IF(L5="","",L5+M5) | O5: 46200 | P5: Pagada | Q5: 89392.8 | R5: =IF(N5="","",MAX(N5-Q5,0)) | S5: =IF(A5="","",IF(OR(P5="Pagada",R5=0),"Pagada",IF(O5<TODAY(),"Vencida",IF(O5<=TODAY()+Inicio!$B$19,"Próxima a vencer","Vigente")))) | U5: =IF($B5="","",YEAR($B5)) | V5: =IF($B5="","",MONTH($B5)) | W5: =IF($B5="","",DAY($B5)) | X5: =IF($B5="","",YEAR($B5)&"-"&TEXT(MONTH($B5),"00")) | Y5: =IF(OR($H5="",$J5=""),"",$J5*IFERROR(VLOOKUP($H5,Maestro_SKU!$A$2:$P$500,12,FALSE),1))
A6: V-0005 | B6: 46197 | C6: F-202607005 | D6: PDV-004 | E6: =IFERROR(VLOOKUP(D6,Clientes_PDV!$A$2:$J$250,2,FALSE),"") | F6: =IFERROR(VLOOKUP(D6,Clientes_PDV!$A$2:$J$250,3,FALSE),"") | G6: =IFERROR(VLOOKUP(D6,Clientes_PDV!$A$2:$J$250,4,FALSE),"") | H6: NUVA-BAR-PB-CS-24 | I6: =IFERROR(VLOOKUP(H6,Maestro_SKU!$A$2:$P$500,2,FALSE),"") | J6: 20 | K6: 17022 | L6: =IF(OR(J6="",K6=""),"",J6*K6) | M6: =IF(L6="","",L6*Inicio!$B$13) | N6: =IF(L6="","",L6+M6) | O6: 46212 | P6: Pagada | Q6: 405123.6 | R6: =IF(N6="","",MAX(N6-Q6,0)) | S6: =IF(A6="","",IF(OR(P6="Pagada",R6=0),"Pagada",IF(O6<TODAY(),"Vencida",IF(O6<=TODAY()+Inicio!$B$19,"Próxima a vencer","Vigente")))) | U6: =IF($B6="","",YEAR($B6)) | V6: =IF($B6="","",MONTH($B6)) | W6: =IF($B6="","",DAY($B6)) | X6: =IF($B6="","",YEAR($B6)&"-"&TEXT(MONTH($B6),"00")) | Y6: =IF(OR($H6="",$J6=""),"",$J6*IFERROR(VLOOKUP($H6,Maestro_SKU!$A$2:$P$500,12,FALSE),1))
A7: V-0006 | B7: 46177 | C7: F-202607006 | D7: PDV-005 | E7: =IFERROR(VLOOKUP(D7,Clientes_PDV!$A$2:$J$250,2,FALSE),"") | F7: =IFERROR(VLOOKUP(D7,Clientes_PDV!$A$2:$J$250,3,FALSE),"") | G7: =IFERROR(VLOOKUP(D7,Clientes_PDV!$A$2:$J$250,4,FALSE),"") | H7: NUVA-BAR-CC-CS-24 | I7: =IFERROR(VLOOKUP(H7,Maestro_SKU!$A$2:$P$500,2,FALSE),"") | J7: 15 | K7: 17698 | L7: =IF(OR(J7="",K7=""),"",J7*K7) | M7: =IF(L7="","",L7*Inicio!$B$13) | N7: =IF(L7="","",L7+M7) | O7: 46222 | P7: Pagada | Q7: 315909.3 | R7: =IF(N7="","",MAX(N7-Q7,0)) | S7: =IF(A7="","",IF(OR(P7="Pagada",R7=0),"Pagada",IF(O7<TODAY(),"Vencida",IF(O7<=TODAY()+Inicio!$B$19,"Próxima a vencer","Vigente")))) | U7: =IF($B7="","",YEAR($B7)) | V7: =IF($B7="","",MONTH($B7)) | W7: =IF($B7="","",DAY($B7)) | X7: =IF($B7="","",YEAR($B7)&"-"&TEXT(MONTH($B7),"00")) | Y7: =IF(OR($H7="",$J7=""),"",$J7*IFERROR(VLOOKUP($H7,Maestro_SKU!$A$2:$P$500,12,FALSE),1))
A8: V-0007 | B8: 46197 | C8: F-202607007 | D8: PDV-002 | E8: =IFERROR(VLOOKUP(D8,Clientes_PDV!$A$2:$J$250,2,FALSE),"") | F8: =IFERROR(VLOOKUP(D8,Clientes_PDV!$A$2:$J$250,3,FALSE),"") | G8: =IFERROR(VLOOKUP(D8,Clientes_PDV!$A$2:$J$250,4,FALSE),"") | H8: NUVA-BAR-CC-BX-04 | I8: =IFERROR(VLOOKUP(H8,Maestro_SKU!$A$2:$P$500,2,FALSE),"") | J8: 8 | K8: 3268 | L8: =IF(OR(J8="",K8=""),"",J8*K8) | M8: =IF(L8="","",L8*Inicio!$B$13) | N8: =IF(L8="","",L8+M8) | O8: 46197 | P8: Pagada | Q8: 31111.36 | R8: =IF(N8="","",MAX(N8-Q8,0)) | S8: =IF(A8="","",IF(OR(P8="Pagada",R8=0),"Pagada",IF(O8<TODAY(),"Vencida",IF(O8<=TODAY()+Inicio!$B$19,"Próxima a vencer","Vigente")))) | U8: =IF($B8="","",YEAR($B8)) | V8: =IF($B8="","",MONTH($B8)) | W8: =IF($B8="","",DAY($B8)) | X8: =IF($B8="","",YEAR($B8)&"-"&TEXT(MONTH($B8),"00")) | Y8: =IF(OR($H8="",$J8=""),"",$J8*IFERROR(VLOOKUP($H8,Maestro_SKU!$A$2:$P$500,12,FALSE),1))
A9: V-0008 | B9: 46152 | C9: F-202607008 | D9: PDV-005 | E9: =IFERROR(VLOOKUP(D9,Clientes_PDV!$A$2:$J$250,2,FALSE),"") | F9: =IFERROR(VLOOKUP(D9,Clientes_PDV!$A$2:$J$250,3,FALSE),"") | G9: =IFERROR(VLOOKUP(D9,Clientes_PDV!$A$2:$J$250,4,FALSE),"") | H9: NUVA-BAR-PB-U-01 | I9: =IFERROR(VLOOKUP(H9,Maestro_SKU!$A$2:$P$500,2,FALSE),"") | J9: 6 | K9: 745 | L9: =IF(OR(J9="",K9=""),"",J9*K9) | M9: =IF(L9="","",L9*Inicio!$B$13) | N9: =IF(L9="","",L9+M9) | O9: 46182 | P9: Vencida | Q9: 0 | R9: =IF(N9="","",MAX(N9-Q9,0)) | S9: =IF(A9="","",IF(OR(P9="Pagada",R9=0),"Pagada",IF(O9<TODAY(),"Vencida",IF(O9<=TODAY()+Inicio!$B$19,"Próxima a vencer","Vigente")))) | U9: =IF($B9="","",YEAR($B9)) | V9: =IF($B9="","",MONTH($B9)) | W9: =IF($B9="","",DAY($B9)) | X9: =IF($B9="","",YEAR($B9)&"-"&TEXT(MONTH($B9),"00")) | Y9: =IF(OR($H9="",$J9=""),"",$J9*IFERROR(VLOOKUP($H9,Maestro_SKU!$A$2:$P$500,12,FALSE),1))
A10: V-0009 | B10: 46161 | C10: F-202607009 | D10: PDV-003 | E10: =IFERROR(VLOOKUP(D10,Clientes_PDV!$A$2:$J$250,2,FALSE),"") | F10: =IFERROR(VLOOKUP(D10,Clientes_PDV!$A$2:$J$250,3,FALSE),"") | G10: =IFERROR(VLOOKUP(D10,Clientes_PDV!$A$2:$J$250,4,FALSE),"") | H10: NUVA-BAR-PB-U-01 | I10: =IFERROR(VLOOKUP(H10,Maestro_SKU!$A$2:$P$500,2,FALSE),"") | J10: 6 | K10: 851 | L10: =IF(OR(J10="",K10=""),"",J10*K10) | M10: =IF(L10="","",L10*Inicio!$B$13) | N10: =IF(L10="","",L10+M10) | O10: 46176 | P10: Vencida | Q10: 0 | R10: =IF(N10="","",MAX(N10-Q10,0)) | S10: =IF(A10="","",IF(OR(P10="Pagada",R10=0),"Pagada",IF(O10<TODAY(),"Vencida",IF(O10<=TODAY()+Inicio!$B$19,"Próxima a vencer","Vigente")))) | U10: =IF($B10="","",YEAR($B10)) | V10: =IF($B10="","",MONTH($B10)) | W10: =IF($B10="","",DAY($B10)) | X10: =IF($B10="","",YEAR($B10)&"-"&TEXT(MONTH($B10),"00")) | Y10: =IF(OR($H10="",$J10=""),"",$J10*IFERROR(VLOOKUP($H10,Maestro_SKU!$A$2:$P$500,12,FALSE),1))
A11: V-0010 | B11: 46203 | C11: F-202607010 | D11: PDV-007 | E11: =IFERROR(VLOOKUP(D11,Clientes_PDV!$A$2:$J$250,2,FALSE),"") | F11: =IFERROR(VLOOKUP(D11,Clientes_PDV!$A$2:$J$250,3,FALSE),"") | G11: =IFERROR(VLOOKUP(D11,Clientes_PDV!$A$2:$J$250,4,FALSE),"") | H11: NUVA-BAR-BM-CS-24 | I11: =IFERROR(VLOOKUP(H11,Maestro_SKU!$A$2:$P$500,2,FALSE),"") | J11: 24 | K11: 18767 | L11: =IF(OR(J11="",K11=""),"",J11*K11) | M11: =IF(L11="","",L11*Inicio!$B$13) | N11: =IF(L11="","",L11+M11) | O11: 46218 | P11: Parcial | Q11: 205558 | R11: =IF(N11="","",MAX(N11-Q11,0)) | S11: =IF(A11="","",IF(OR(P11="Pagada",R11=0),"Pagada",IF(O11<TODAY(),"Vencida",IF(O11<=TODAY()+Inicio!$B$19,"Próxima a vencer","Vigente")))) | U11: =IF($B11="","",YEAR($B11)) | V11: =IF($B11="","",MONTH($B11)) | W11: =IF($B11="","",DAY($B11)) | X11: =IF($B11="","",YEAR($B11)&"-"&TEXT(MONTH($B11),"00")) | Y11: =IF(OR($H11="",$J11=""),"",$J11*IFERROR(VLOOKUP($H11,Maestro_SKU!$A$2:$P$500,12,FALSE),1))
