Workbook
Name cfg_AnioResumen: Resumen!$B$3
Name cfg_DiasCobertura: Inicio!$B$29
Name cfg_DiasVencer: Inicio!$B$19
Name cfg_IVA: Inicio!$B$13
Name cfg_MontoPendiente: Inicio!$B$18
Name cfg_PctSeguridad: Inicio!$B$30
Name cfg_StockCritico: Inicio!$B$16
Name cfg_StockObservar: Inicio!$B$17
Name cfg_VentaAlta: Inicio!$B$34
Name cfg_VentaBaja: Inicio!$B$15
Name cfg_VentanaDemanda: Inicio!$B$31
Name cfg_VentaRecienteDias: Inicio!$B$14
Name lst_Bodega: Bodegas!$A$2:$A$50
Name lst_Canal: Inicio!$E$5:$E$13
Name lst_CondPago: Inicio!$H$5:$H$9
Name lst_EstadoCliente: Inicio!$G$5:$G$8
Name lst_Frecuencia: Inicio!$K$5:$K$7
Name lst_StatusPago: Inicio!$F$5:$F$9
Name rng_PDV: Clientes_PDV!$A$2:$A$250
Name rng_SKU: Maestro_SKU!$A$2:$A$500

Sheet Inicio
A1: NUVA OXI · Control Comercial — CONFIDENCIAL Y RESTRINGIDO (uso interno)
A2: GUÍA — cómo funciona, se edita, se alimenta y crece (clic aquí)
A3: Cómo se usa en simple | E3: Listas editables para desplegables
A4: 1 | B4: Dashboard: mirar cada lunes qué está en rojo o prioridad alta. | E4: Canal | F4: Status pago | G4: Estado cliente | H4: Condición pago | I4: Prioridad | J4: Estado stock | K4: Frecuencia
A5: 2 | B5: Cobertura: revisar el detalle por punto de venta, visita, venta, pago y stock. | E5: Retail | F5: Pendiente | G5: Activo | H5: Contado | I5: Alta | J5: Crítico | K5: Semanal
A6: 3 | B6: Clientes_PDV: agregar nuevos clientes o salas. Esa hoja alimenta Cobertura. | E6: Conveniencia | F6: Pagada | G6: Pausado | H6: Crédito 15 días | I6: Media | J6: Observar | K6: Quincenal
A7: 4 | B7: Ventas_SellIn: ingresar facturas reales. No usar PVP; solo precio neto facturado. | E7: Farmacias | F7: Parcial | G7: Prospecto | H7: Crédito 30 días | I7: Baja | J7: OK | K7: Mensual
A8: 5 | B8: Margen_Frontal: simular precio/margen aparte, sin afectar ventas ni cobertura. | E8: Especializadas | F8: Vencida | G8: Inactivo | H8: Crédito 45 días
A9: 6 | B9: SellOut_Jumbo: pegar exportaciones futuras de Cencosud/Jumbo cuando existan. | E9: HORECA | F9: Nota crédito | H9: Crédito 60 días
E10: Tradicional
A11: Condiciones editables | E11: Ecommerce
A12: Condición | B12: Valor editable | C12: Qué significa | E12: Corporativo
A13: IVA | B13: 0.19 | C13: Se usa para pasar neto a bruto y viceversa. | E13: Distribuidor
A14: Venta reciente últimos días | B14: 30 | C14: Período usado en cobertura y dashboard.
A15: Venta baja si es menor a | B15: 500000 | C15: Si venta neta 30d queda bajo este monto, se marca baja. | E15: Leyenda
A16: Stock crítico PDV barras | B16: 8 | C16: Barras equivalentes en sala bajo este nivel = crítico. | E16: Amarillo | F16: Dato editable
A17: Stock en observación PDV barras | B17: 20 | C17: Barras equivalentes en sala bajo este nivel = observar. | E17: Gris | F17: Fórmula; no tocar
A18: Monto pendiente relevante | B18: 100000 | C18: Deuda sobre este monto eleva prioridad. | E18: Morado | F18: Título/encabezado
A19: Factura próxima a vencer días | B19: 7 | C19: Días hacia adelante para marcar próxima a vencer.
A21: Regla: NETO = sin IVA (lo que facturas y analizas). Con IVA = lo que se paga y cobra.
A22: Frecuencia de visita
A23: Frecuencia | B23: Días máximos | C23: Regla
A24: Semanal | B24: 7 | C24: Atrasado desde 8 días
A25: Quincenal | B25: 15 | C25: Atrasado desde 16 días
A26: Mensual | B26: 30 | C26: Atrasado desde 31 días
A28: Parámetros de inventario (editable)
A29: Días de cobertura objetivo | B29: 30 | C29: Cuántos días de venta quieres tener en stock
A30: % stock de seguridad | B30: 0.2 | C30: Colchón sobre el objetivo ante quiebres
A31: Ventana de demanda (días) | B31: 30 | C31: Período de sell-in para el promedio (30/60/90)
A33: Reglas de rotación (editable)
A34: Rotación ALTA: venta 30d ≥ | B34: 1000000 | C34: Sobre este monto, el PDV rota bien
A35: Rotación BAJA: venta 30d < | B35: =B15 -> 500000 | C35: Usa el mismo umbral de 'Venta baja' (B15)
A36: Rotación MEDIA: | B36: entre ambos | C36: Entre el monto de BAJA y el de ALTA
A38: Qué define cada estado (los valores se editan arriba)
A39: Stock CRÍTICO: barras ≤ | B39: =B16 -> 8
A40: Stock OBSERVAR: barras ≤ | B40: =B17 -> 20
A41: Venta BAJA: venta 30d < | B41: =B15 -> 500000
A42: Deuda RELEVANTE: monto ≥ | B42: =B18 -> 100000
A43: Rotación ALTA: venta 30d ≥ | B43: =B34 -> 1000000
A44: Factura POR VENCER: días ≤ | B44: =B19 -> 7
...

Sheet Guia
A1: Guía rápida para Ana | Cómo leer y cargar el archivo
A3: Objetivo del archivo
A4: Ayudar a decidir cada lunes qué puntos de venta visitar, cuáles están vendiendo, cuáles tienen facturas pendientes y dónde falta stock. No busca reemplazar ERP ni contabilidad.
A6: Qué mirar primero
A7: • | B7: 1. Abrir Dashboard y revisar prioridad alta.
A8: • | B8: 2. Ir a Cobertura para ver la razón: visita atrasada, sin venta, deuda o stock crítico y *Revisar en Clientes_PDV la ultima visita.
A9: • | B9: 3. Filtrar por Canal o Cliente si se saldrá a terreno por zona/cuenta.
A11: Dónde cargar información
A12: • | B12: Clientes nuevos o nuevas salas: Clientes_PDV.
A13: • | B13: Facturas/sell-in: Ventas_SellIn. Ingresar fecha, factura, PDV_ID, SKU, cantidad, precio neto facturado y status de pago.
A14: • | B14: Stock observado en terreno: Stock_PDV.
A15: • | B15: Sell-out de Jumbo/Cencosud: SellOut_Jumbo, cuando exista exportación.
A16: • | B16: Simulación de precio y margen: Margen_Frontal.
A18: Regla de colores
A19: • | B19: Amarillo = se puede editar.
A20: • | B20: Gris = fórmula, mejor no tocar.
A21: • | B21: Morado = encabezado o título.
A22: • | B22: Si algo sale raro, revisar primero si falta PDV_ID, SKU o fecha.
A24: Conceptos simples
A25: • | B25: Sell-in: venta facturada al cliente o punto de venta.
A26: • | B26: Sell-out: venta desde la sala hacia consumidor final, cuando el retailer la informe.
A27: • | B27: Margen frontal: margen que el cliente obtiene entre el PVP neto y el precio neto que le facturamos.
A28: • | B28: Barras equivalentes: convierte unidades, estuches y cajas master a barras para comparar stock y venta.
A29: Regla de dinero: NETO = sin IVA (ventas y análisis). Con IVA = pagos, deuda y facturas.
A30: Cómo se edita, se alimenta y crece
A31: 1. | B31: Editar: solo celdas AMARILLAS. Las grises son fórmulas (se calculan solas).
A32: 2. | B32: Alimentar ventas: Ventas_SellIn, una fila por factura (usa los desplegables).
A33: 3. | B33: Terreno: registra visitas y stock de sala en Clientes_PDV y Stock_PDV.
A34: 4. | B34: Producto nuevo: agrégalo en Maestro_SKU; aparece solo en el plan y en las listas.
A35: 5. | B35: Cliente/sala nueva: agrégala en Clientes_PDV; aparece sola en Cobertura.
A36: 6. | B36: Inventario: escribe tu bodega en Plan_Inventario; te dice cuánto reponer.
A37: 7. | B37: Ajustes: cambia umbrales (venta, stock, cobertura, rotación) en Inicio, sin tocar fórmulas.
A38: 8. | B38: Crece hasta: 250 clientes/PDV y 800 facturas. Para más, se estiran los rangos.

Sheet Dashboard
A1: Dashboard semanal · Revisión del lunes — CONFIDENCIAL
B3: Indicador | C3: Valor | E3: Parámetros activos (se leen desde Inicio) | F3: Valor
B4: Fecha control | C4: =TODAY() -> 46213 | E4: Venta reciente días | F4: =Inicio!B14 -> 30
B5: PDV activos | C5: =COUNTIF(Clientes_PDV!$I$2:$I$250,"Activo") -> 11 | E5: Venta baja menor a | F5: =Inicio!B15 -> 500000
B6: PDV prioridad alta | C6: =COUNTIF(Cobertura!$Q$2:$Q$250,"Alta") -> 10 | E6: Semanal días | F6: =Inicio!B24 -> 7
B7: Venta sell-in 30d NETA (sin IVA) | C7: =SUM(Cobertura!$I$2:$I$250) -> 2871252 | E7: Quincenal días | F7: =Inicio!B25 -> 15
B8: Deuda total (con IVA) | C8: =SUM(Cobertura!$M$2:$M$250) -> 2688041.9 | E8: Mensual días | F8: =Inicio!B26 -> 30
B9: PDV stock crítico | C9: =COUNTIF(Cobertura!$P$2:$P$250,"Crítico") -> 4 | E9: Factura próxima a vencer | F9: =Inicio!B19 -> 7
B11: ⚙ Ir a Configuración (hoja Inicio)
B12: Puntos de venta a gestionar esta semana
A13: ID | B13: Punto de venta | C13: Cliente | D13: Canal | E13: Estado visita | F13: Estado venta | G13: Estado pago | H13: Estado stock | I13: Prioridad
A14: =Cobertura!A2 -> PDV-001 | B14: =Cobertura!D2 -> Jumbo Bilbao | C14: =Cobertura!B2 -> Jumbo | D14: =Cobertura!C2 -> Retail | E14: =Cobertura!H2 -> Vigente | F14: =Cobertura!K2 -> Venta baja | G14: =Cobertura!N2 -> Pendiente menor | H14: =Cobertura!P2 -> OK | I14: =Cobertura!Q2 -> Media
A15: =Cobertura!A3 -> PDV-002 | B15: =Cobertura!D3 -> Jumbo Kennedy | C15: =Cobertura!B3 -> Jumbo | D15: =Cobertura!C3 -> Retail | E15: =Cobertura!H3 -> Atrasado | F15: =Cobertura!K3 -> Venta baja | G15: =Cobertura!N3 -> Sin deuda | H15: =Cobertura!P3 -> Crítico | I15: =Cobertura!Q3 -> Alta
A16: =Cobertura!A4 -> PDV-003 | B16: =Cobertura!D4 -> Jumbo La Reina | C16: =Cobertura!B4 -> Jumbo | D16: =Cobertura!C4 -> Retail | E16: =Cobertura!H4 -> Atrasado | F16: =Cobertura!K4 -> Venta baja | G16: =Cobertura!N4 -> Pendiente menor | H16: =Cobertura!P4 -> OK | I16: =Cobertura!Q4 -> Alta
A17: =Cobertura!A5 -> PDV-004 | B17: =Cobertura!D5 -> Get It Apoquindo | C17: =Cobertura!B5 -> Get It | D17: =Cobertura!C5 -> Conveniencia | E17: =Cobertura!H5 -> Vigente | F17: =Cobertura!K5 -> Venta baja | G17: =Cobertura!N5 -> Pendiente menor | H17: =Cobertura!P5 -> Crítico | I17: =Cobertura!Q5 -> Alta
A18: =Cobertura!A6 -> PDV-005 | B18: =Cobertura!D6 -> Get It Vitacura | C18: =Cobertura!B6 -> Get It | D18: =Cobertura!C6 -> Conveniencia | E18: =Cobertura!H6 -> Atrasado | F18: =Cobertura!K6 -> Venta OK | G18: =Cobertura!N6 -> Pendiente relevante | H18: =Cobertura!P6 -> OK | I18: =Cobertura!Q6 -> Alta
A19: =Cobertura!A7 -> PDV-006 | B19: =Cobertura!D7 -> Aldea Nativa Providencia | C19: =Cobertura!B7 -> Aldea Nativa | D19: =Cobertura!C7 -> Especializadas | E19: =Cobertura!H7 -> Atrasado | F19: =Cobertura!K7 -> Venta baja | G19: =Cobertura!N7 -> Pendiente menor | H19: =Cobertura!P7 -> OK | I19: =Cobertura!Q7 -> Alta
A20: =Cobertura!A8 -> PDV-007 | B20: =Cobertura!D8 -> All Nutrition La Reina | C20: =Cobertura!B8 -> All Nutrition | D20: =Cobertura!C8 -> Especializadas | E20: =Cobertura!H8 -> Atrasado | F20: =Cobertura!K8 -> Venta baja | G20: =Cobertura!N8 -> Pendiente relevante | H20: =Cobertura!P8 -> OK | I20: =Cobertura!Q8 -> Alta
A21: =Cobertura!A9 -> PDV-008 | B21: =Cobertura!D9 -> Ahumada Los Dominicos | C21: =Cobertura!B9 -> Farmacia Ahumada | D21: =Cobertura!C9 -> Farmacias | E21: =Cobertura!H9 -> Vigente | F21: =Cobertura!K9 -> Venta baja | G21: =Cobertura!N9 -> Pendiente menor | H21: =Cobertura!P9 -> Crítico | I21: =Cobertura!Q9 -> Alta
A22: =Cobertura!A10 -> PDV-009 | B22: =Cobertura!D10 -> Cruz Verde Vitacura | C22: =Cobertura!B10 -> Cruz Verde | D22: =Cobertura!C10 -> Farmacias | E22: =Cobertura!H10 -> Atrasado | F22: =Cobertura!K10 -> Venta baja | G22: =Cobertura!N10 -> Pendiente relevante | H22: =Cobertura!P10 -> OK | I22: =Cobertura!Q10 -> Alta
A23: =Cobertura!A11 -> PDV-010 | B23: =Cobertura!D11 -> Sodexo Casa Matriz | C23: =Cobertura!B11 -> Sodexo | D23: =Cobertura!C11 -> Corporativo | E23: =Cobertura!H11 -> Vigente | F23: =Cobertura!K11 -> Venta baja | G23: =Cobertura!N11 -> Pendiente relevante | H23: =Cobertura!P11 -> Crítico | I23: =Cobertura!Q11 -> Alta
A24: =Cobertura!A12 -> PDV-011 | B24: =Cobertura!D12 -> Tres Toques Vitacura | C24: =Cobertura!B12 -> Tres Toques | D24: =Cobertura!C12 -> HORECA | E24: =Cobertura!H12 -> Vigente | F24: =Cobertura!K12 -> Venta baja | G24: =Cobertura!N12 -> Pendiente menor | H24: =Cobertura!P12 -> OK | I24: =Cobertura!Q12 -> Media
A25: =Cobertura!A13 -> PDV-012 | B25: =Cobertura!D13 -> Mundo del Vino Escuela Militar | C25: =Cobertura!B13 -> Mundo del Vino | D25: =Cobertura!C13 -> Especializadas | E25: =Cobertura!H13 -> Vigente | F25: =Cobertura!K13 -> Venta baja | G25: =Cobertura!N13 -> Pendiente relevante | H25: =Cobertura!P13 -> OK | I25: =Cobertura!Q13 -> Alta
A28: Venta acumulada NETA (sin IVA) | D28: Venta acumulada por punto de venta
A29: Desde: | B29: 46023 | C29: (hasta hoy) | D29: Punto de venta | E29: Cliente | F29: Canal | G29: Venta neta acum. | H29: Dirección
A30: Total acumulado: | B30: =SUMIFS(Ventas_SellIn!$L$2:$L$800,Ventas_SellIn!$B$2:$B$800,">="&$B$29) -> 5894865 | D30: =IF(Clientes_PDV!A2="","",Clientes_PDV!D2) -> Jumbo Bilbao | E30: =IF(Clientes_PDV!A2="","",Clientes_PDV!B2) -> Jumbo | F30: =IF(Clientes_PDV!A2="","",Clientes_PDV!C2) -> Retail | G30: =IF(Clientes_PDV!A2="","",SUMIFS(Ventas_SellIn!$L$2:$L$800,Ventas_SellIn!$D$2:$D$800,Clientes_PDV!A2,Ventas_SellIn!$B$2:$B$800,">="&$B$29)) -> 411396 | H30: =IF(Clientes_PDV!A2="","",Clientes_PDV!K2) -> 0
D31: =IF(Clientes_PDV!A3="","",Clientes_PDV!D3) -> Jumbo Kennedy | E31: =IF(Clientes_PDV!A3="","",Clientes_PDV!B3) -> Jumbo | F31: =IF(Clientes_PDV!A3="","",Clientes_PDV!C3) -> Retail | G31: =IF(Clientes_PDV!A3="","",SUMIFS(Ventas_SellIn!$L$2:$L$800,Ventas_SellIn!$D$2:$D$800,Clientes_PDV!A3,Ventas_SellIn!$B$2:$B$800,">="&$B$29)) -> 523920 | H31: =IF(Clientes_PDV!A3="","",Clientes_PDV!K3) -> 0
A32: Canal | B32: Venta neta acum. | D32: =IF(Clientes_PDV!A4="","",Clientes_PDV!D4) -> Jumbo La Reina | E32: =IF(Clientes_PDV!A4="","",Clientes_PDV!B4) -> Jumbo | F32: =IF(Clientes_PDV!A4="","",Clientes_PDV!C4) -> Retail | G32: =IF(Clientes_PDV!A4="","",SUMIFS(Ventas_SellIn!$L$2:$L$800,Ventas_SellIn!$D$2:$D$800,Clientes_PDV!A4,Ventas_SellIn!$B$2:$B$800,">="&$B$29)) -> 71326 | H32: =IF(Clientes_PDV!A4="","",Clientes_PDV!K4) -> 0
A33: =Inicio!$E$5 -> Retail | B33: =IF($A33="","",SUMIFS(Ventas_SellIn!$L$2:$L$800,Ventas_SellIn!$F$2:$F$800,$A33,Ventas_SellIn!$B$2:$B$800,">="&$B$29)) -> 1006642 | D33: =IF(Clientes_PDV!A5="","",Clientes_PDV!D5) -> Get It Apoquindo | E33: =IF(Clientes_PDV!A5="","",Clientes_PDV!B5) -> Get It | F33: =IF(Clientes_PDV!A5="","",Clientes_PDV!C5) -> Conveniencia | G33: =IF(Clientes_PDV!A5="","",SUMIFS(Ventas_SellIn!$L$2:$L$800,Ventas_SellIn!$D$2:$D$800,Clientes_PDV!A5,Ventas_SellIn!$B$2:$B$800,">="&$B$29)) -> 368880 | H33: =IF(Clientes_PDV!A5="","",Clientes_PDV!K5) -> 0
A34: =Inicio!$E$6 -> Conveniencia | B34: =IF($A34="","",SUMIFS(Ventas_SellIn!$L$2:$L$800,Ventas_SellIn!$F$2:$F$800,$A34,Ventas_SellIn!$B$2:$B$800,">="&$B$29)) -> 1713268 | D34: =IF(Clientes_PDV!A6="","",Clientes_PDV!D6) -> Get It Vitacura | E34: =IF(Clientes_PDV!A6="","",Clientes_PDV!B6) -> Get It | F34: =IF(Clientes_PDV!A6="","",Clientes_PDV!C6) -> Conveniencia | G34: =IF(Clientes_PDV!A6="","",SUMIFS(Ventas_SellIn!$L$2:$L$800,Ventas_SellIn!$D$2:$D$800,Clientes_PDV!A6,Ventas_SellIn!$B$2:$B$800,">="&$B$29)) -> 1344388 | H34: =IF(Clientes_PDV!A6="","",Clientes_PDV!K6) -> 0
A35: =Inicio!$E$7 -> Farmacias | B35: =IF($A35="","",SUMIFS(Ventas_SellIn!$L$2:$L$800,Ventas_SellIn!$F$2:$F$800,$A35,Ventas_SellIn!$B$2:$B$800,">="&$B$29)) -> 723604 | D35: =IF(Clientes_PDV!A7="","",Clientes_PDV!D7) -> Aldea Nativa Providencia | E35: =IF(Clientes_PDV!A7="","",Clientes_PDV!B7) -> Aldea Nativa | F35: =IF(Clientes_PDV!A7="","",Clientes_PDV!C7) -> Especializadas | G35: =IF(Clientes_PDV!A7="","",SUMIFS(Ventas_SellIn!$L$2:$L$800,Ventas_SellIn!$D$2:$D$800,Clientes_PDV!A7,Ventas_SellIn!$B$2:$B$800,">="&$B$29)) -> 552872 | H35: =IF(Clientes_PDV!A7="","",Clientes_PDV!K7) -> 0
A36: =Inicio!$E$8 -> Especializadas | B36: =IF($A36="","",SUMIFS(Ventas_SellIn!$L$2:$L$800,Ventas_SellIn!$F$2:$F$800,$A36,Ventas_SellIn!$B$2:$B$800,">="&$B$29)) -> 1735473 | D36: =IF(Clientes_PDV!A8="","",Clientes_PDV!D8) -> All Nutrition La Reina | E36: =IF(Clientes_PDV!A8="","",Clientes_PDV!B8) -> All Nutrition | F36: =IF(Clientes_PDV!A8="","",Clientes_PDV!C8) -> Especializadas | G36: =IF(Clientes_PDV!A8="","",SUMIFS(Ventas_SellIn!$L$2:$L$800,Ventas_SellIn!$D$2:$D$800,Clientes_PDV!A8,Ventas_SellIn!$B$2:$B$800,">="&$B$29)) -> 771763 | H36: =IF(Clientes_PDV!A8="","",Clientes_PDV!K8) -> 0
A37: =Inicio!$E$9 -> HORECA | B37: =IF($A37="","",SUMIFS(Ventas_SellIn!$L$2:$L$800,Ventas_SellIn!$F$2:$F$800,$A37,Ventas_SellIn!$B$2:$B$800,">="&$B$29)) -> 108624 | D37: =IF(Clientes_PDV!A9="","",Clientes_PDV!D9) -> Ahumada Los Dominicos | E37: =IF(Clientes_PDV!A9="","",Clientes_PDV!B9) -> Farmacia Ahumada | F37: =IF(Clientes_PDV!A9="","",Clientes_PDV!C9) -> Farmacias | G37: =IF(Clientes_PDV!A9="","",SUMIFS(Ventas_SellIn!$L$2:$L$800,Ventas_SellIn!$D$2:$D$800,Clientes_PDV!A9,Ventas_SellIn!$B$2:$B$800,">="&$B$29)) -> 12984 | H37: =IF(Clientes_PDV!A9="","",Clientes_PDV!K9) -> 0
A38: =Inicio!$E$10 -> Tradicional | B38: =IF($A38="","",SUMIFS(Ventas_SellIn!$L$2:$L$800,Ventas_SellIn!$F$2:$F$800,$A38,Ventas_SellIn!$B$2:$B$800,">="&$B$29)) -> 0 | D38: =IF(Clientes_PDV!A10="","",Clientes_PDV!D10) -> Cruz Verde Vitacura | E38: =IF(Clientes_PDV!A10="","",Clientes_PDV!B10) -> Cruz Verde | F38: =IF(Clientes_PDV!A10="","",Clientes_PDV!C10) -> Farmacias | G38: =IF(Clientes_PDV!A10="","",SUMIFS(Ventas_SellIn!$L$2:$L$800,Ventas_SellIn!$D$2:$D$800,Clientes_PDV!A10,Ventas_SellIn!$B$2:$B$800,">="&$B$29)) -> 710620 | H38: =IF(Clientes_PDV!A10="","",Clientes_PDV!K10) -> 0
A39: =Inicio!$E$11 -> Ecommerce | B39: =IF($A39="","",SUMIFS(Ventas_SellIn!$L$2:$L$800,Ventas_SellIn!$F$2:$F$800,$A39,Ventas_SellIn!$B$2:$B$800,">="&$B$29)) -> 0 | D39: =IF(Clientes_PDV!A11="","",Clientes_PDV!D11) -> Sodexo Casa Matriz | E39: =IF(Clientes_PDV!A11="","",Clientes_PDV!B11) -> Sodexo | F39: =IF(Clientes_PDV!A11="","",Clientes_PDV!C11) -> Corporativo | G39: =IF(Clientes_PDV!A11="","",SUMIFS(Ventas_SellIn!$L$2:$L$800,Ventas_SellIn!$D$2:$D$800,Clientes_PDV!A11,Ventas_SellIn!$B$2:$B$800,">="&$B$29)) -> 607254 | H39: =IF(Clientes_PDV!A11="","",Clientes_PDV!K11) -> 0
A40: =Inicio!$E$12 -> Corporativo | B40: =IF($A40="","",SUMIFS(Ventas_SellIn!$L$2:$L$800,Ventas_SellIn!$F$2:$F$800,$A40,Ventas_SellIn!$B$2:$B$800,">="&$B$29)) -> 607254 | D40: =IF(Clientes_PDV!A12="","",Clientes_PDV!D12) -> Tres Toques Vitacura | E40: =IF(Clientes_PDV!A12="","",Clientes_PDV!B12) -> Tres Toques | F40: =IF(Clientes_PDV!A12="","",Clientes_PDV!C12) -> HORECA | G40: =IF(Clientes_PDV!A12="","",SUMIFS(Ventas_SellIn!$L$2:$L$800,Ventas_SellIn!$D$2:$D$800,Clientes_PDV!A12,Ventas_SellIn!$B$2:$B$800,">="&$B$29)) -> 108624 | H40: =IF(Clientes_PDV!A12="","",Clientes_PDV!K12) -> 0
A41: =Inicio!$E$13 -> Distribuidor | B41: =IF($A41="","",SUMIFS(Ventas_SellIn!$L$2:$L$800,Ventas_SellIn!$F$2:$F$800,$A41,Ventas_SellIn!$B$2:$B$800,">="&$B$29)) -> 0 | D41: =IF(Clientes_PDV!A13="","",Clientes_PDV!D13) -> Mundo del Vino Escuela Militar | E41: =IF(Clientes_PDV!A13="","",Clientes_PDV!B13) -> Mundo del Vino | F41: =IF(Clientes_PDV!A13="","",Clientes_PDV!C13) -> Especializadas | G41: =IF(Clientes_PDV!A13="","",SUMIFS(Ventas_SellIn!$L$2:$L$800,Ventas_SellIn!$D$2:$D$800,Clientes_PDV!A13,Ventas_SellIn!$B$2:$B$800,">="&$B$29)) -> 410838 | H41: =IF(Clientes_PDV!A13="","",Clientes_PDV!K13) -> 0

Sheet Resumen
A1: RESUMEN | Nuva Oxi
A3: Año de análisis: | B3: 2026 | D3: ⚙ Configuración
A5: Seguimiento — terreno vs escritorio | D5: Venta por mes (año en B3)
A6: Indicador | B6: Valor | D6: Periodo | E6: Venta NETA | F6: Unidades | G6: Deuda (c/IVA)
A7: PDV activos | B7: =COUNTIF(Clientes_PDV!$I$2:$I$250,"Activo") -> 11 | D7: =$B$3&"-"&TEXT(1,"00") -> 2026-01 | E7: =SUMIFS(Ventas_SellIn!$L$2:$L$800,Ventas_SellIn!$X$2:$X$800,$D7) -> 0 | F7: =SUMIFS(Ventas_SellIn!$J$2:$J$800,Ventas_SellIn!$X$2:$X$800,$D7) -> 0 | G7: =SUMIFS(Ventas_SellIn!$R$2:$R$800,Ventas_SellIn!$X$2:$X$800,$D7) -> 0
A8: Visita vigente | B8: =COUNTIF(Cobertura!$H$2:$H$250,"Vigente") -> 6 | D8: =$B$3&"-"&TEXT(2,"00") -> 2026-02 | E8: =SUMIFS(Ventas_SellIn!$L$2:$L$800,Ventas_SellIn!$X$2:$X$800,$D8) -> 0 | F8: =SUMIFS(Ventas_SellIn!$J$2:$J$800,Ventas_SellIn!$X$2:$X$800,$D8) -> 0 | G8: =SUMIFS(Ventas_SellIn!$R$2:$R$800,Ventas_SellIn!$X$2:$X$800,$D8) -> 0
A9: Visita atrasada | B9: =COUNTIF(Cobertura!$H$2:$H$250,"Atrasado") -> 6 | D9: =$B$3&"-"&TEXT(3,"00") -> 2026-03 | E9: =SUMIFS(Ventas_SellIn!$L$2:$L$800,Ventas_SellIn!$X$2:$X$800,$D9) -> 0 | F9: =SUMIFS(Ventas_SellIn!$J$2:$J$800,Ventas_SellIn!$X$2:$X$800,$D9) -> 0 | G9: =SUMIFS(Ventas_SellIn!$R$2:$R$800,Ventas_SellIn!$X$2:$X$800,$D9) -> 0
A10: Sin visita | B10: =COUNTIF(Cobertura!$H$2:$H$250,"Sin visita") -> 0 | D10: =$B$3&"-"&TEXT(4,"00") -> 2026-04 | E10: =SUMIFS(Ventas_SellIn!$L$2:$L$800,Ventas_SellIn!$X$2:$X$800,$D10) -> 0 | F10: =SUMIFS(Ventas_SellIn!$J$2:$J$800,Ventas_SellIn!$X$2:$X$800,$D10) -> 0 | G10: =SUMIFS(Ventas_SellIn!$R$2:$R$800,Ventas_SellIn!$X$2:$X$800,$D10) -> 0
A11: PDV con venta OK | B11: =COUNTIF(Cobertura!$K$2:$K$250,"Venta OK") -> 1 | D11: =$B$3&"-"&TEXT(5,"00") -> 2026-05 | E11: =SUMIFS(Ventas_SellIn!$L$2:$L$800,Ventas_SellIn!$X$2:$X$800,$D11) -> 2511263 | F11: =SUMIFS(Ventas_SellIn!$J$2:$J$800,Ventas_SellIn!$X$2:$X$800,$D11) -> 220 | G11: =SUMIFS(Ventas_SellIn!$R$2:$R$800,Ventas_SellIn!$X$2:$X$800,$D11) -> 1427456.9
A12: PDV venta baja | B12: =COUNTIF(Cobertura!$K$2:$K$250,"Venta baja") -> 11 | D12: =$B$3&"-"&TEXT(6,"00") -> 2026-06 | E12: =SUMIFS(Ventas_SellIn!$L$2:$L$800,Ventas_SellIn!$X$2:$X$800,$D12) -> 3110100 | F12: =SUMIFS(Ventas_SellIn!$J$2:$J$800,Ventas_SellIn!$X$2:$X$800,$D12) -> 371 | G12: =SUMIFS(Ventas_SellIn!$R$2:$R$800,Ventas_SellIn!$X$2:$X$800,$D12) -> 1256072.6
A13: PDV sin venta | B13: =COUNTIF(Cobertura!$K$2:$K$250,"Sin venta") -> 0 | D13: =$B$3&"-"&TEXT(7,"00") -> 2026-07 | E13: =SUMIFS(Ventas_SellIn!$L$2:$L$800,Ventas_SellIn!$X$2:$X$800,$D13) -> 273502 | F13: =SUMIFS(Ventas_SellIn!$J$2:$J$800,Ventas_SellIn!$X$2:$X$800,$D13) -> 38 | G13: =SUMIFS(Ventas_SellIn!$R$2:$R$800,Ventas_SellIn!$X$2:$X$800,$D13) -> 4512.48
A14: Prioridad Alta (lunes) | B14: =COUNTIF(Cobertura!$Q$2:$Q$250,"Alta") -> 10 | D14: =$B$3&"-"&TEXT(8,"00") -> 2026-08 | E14: =SUMIFS(Ventas_SellIn!$L$2:$L$800,Ventas_SellIn!$X$2:$X$800,$D14) -> 0 | F14: =SUMIFS(Ventas_SellIn!$J$2:$J$800,Ventas_SellIn!$X$2:$X$800,$D14) -> 0 | G14: =SUMIFS(Ventas_SellIn!$R$2:$R$800,Ventas_SellIn!$X$2:$X$800,$D14) -> 0
A15: Deuda total (con IVA) | B15: =SUM(Cobertura!$M$2:$M$250) -> 2688041.9 | D15: =$B$3&"-"&TEXT(9,"00") -> 2026-09 | E15: =SUMIFS(Ventas_SellIn!$L$2:$L$800,Ventas_SellIn!$X$2:$X$800,$D15) -> 0 | F15: =SUMIFS(Ventas_SellIn!$J$2:$J$800,Ventas_SellIn!$X$2:$X$800,$D15) -> 0 | G15: =SUMIFS(Ventas_SellIn!$R$2:$R$800,Ventas_SellIn!$X$2:$X$800,$D15) -> 0
D16: =$B$3&"-"&TEXT(10,"00") -> 2026-10 | E16: =SUMIFS(Ventas_SellIn!$L$2:$L$800,Ventas_SellIn!$X$2:$X$800,$D16) -> 0 | F16: =SUMIFS(Ventas_SellIn!$J$2:$J$800,Ventas_SellIn!$X$2:$X$800,$D16) -> 0 | G16: =SUMIFS(Ventas_SellIn!$R$2:$R$800,Ventas_SellIn!$X$2:$X$800,$D16) -> 0
D17: =$B$3&"-"&TEXT(11,"00") -> 2026-11 | E17: =SUMIFS(Ventas_SellIn!$L$2:$L$800,Ventas_SellIn!$X$2:$X$800,$D17) -> 0 | F17: =SUMIFS(Ventas_SellIn!$J$2:$J$800,Ventas_SellIn!$X$2:$X$800,$D17) -> 0 | G17: =SUMIFS(Ventas_SellIn!$R$2:$R$800,Ventas_SellIn!$X$2:$X$800,$D17) -> 0
D18: =$B$3&"-"&TEXT(12,"00") -> 2026-12 | E18: =SUMIFS(Ventas_SellIn!$L$2:$L$800,Ventas_SellIn!$X$2:$X$800,$D18) -> 0 | F18: =SUMIFS(Ventas_SellIn!$J$2:$J$800,Ventas_SellIn!$X$2:$X$800,$D18) -> 0 | G18: =SUMIFS(Ventas_SellIn!$R$2:$R$800,Ventas_SellIn!$X$2:$X$800,$D18) -> 0
A19: Nota: se llena solo desde Ventas_SellIn y Cobertura. Cambia el año en B3. | D19: TOTAL | E19: =SUM(E7:E18) -> 5894865 | F19: =SUM(F7:F18) -> 629 | G19: =SUM(G7:G18) -> 2688041.9
A21: Venta por canal
A22: Canal | B22: Venta neta | C22: Unidades
A23: =Inicio!$E$5 -> Retail | B23: =IF($A23="","",SUMIFS(Ventas_SellIn!$L$2:$L$800,Ventas_SellIn!$F$2:$F$800,$A23)) -> 1006642 | C23: =IF($A23="","",SUMIFS(Ventas_SellIn!$J$2:$J$800,Ventas_SellIn!$F$2:$F$800,$A23)) -> 102
A24: =Inicio!$E$6 -> Conveniencia | B24: =IF($A24="","",SUMIFS(Ventas_SellIn!$L$2:$L$800,Ventas_SellIn!$F$2:$F$800,$A24)) -> 1713268 | C24: =IF($A24="","",SUMIFS(Ventas_SellIn!$J$2:$J$800,Ventas_SellIn!$F$2:$F$800,$A24)) -> 143
A25: =Inicio!$E$7 -> Farmacias | B25: =IF($A25="","",SUMIFS(Ventas_SellIn!$L$2:$L$800,Ventas_SellIn!$F$2:$F$800,$A25)) -> 723604 | C25: =IF($A25="","",SUMIFS(Ventas_SellIn!$J$2:$J$800,Ventas_SellIn!$F$2:$F$800,$A25)) -> 86
A26: =Inicio!$E$8 -> Especializadas | B26: =IF($A26="","",SUMIFS(Ventas_SellIn!$L$2:$L$800,Ventas_SellIn!$F$2:$F$800,$A26)) -> 1735473 | C26: =IF($A26="","",SUMIFS(Ventas_SellIn!$J$2:$J$800,Ventas_SellIn!$F$2:$F$800,$A26)) -> 224
A27: =Inicio!$E$9 -> HORECA | B27: =IF($A27="","",SUMIFS(Ventas_SellIn!$L$2:$L$800,Ventas_SellIn!$F$2:$F$800,$A27)) -> 108624 | C27: =IF($A27="","",SUMIFS(Ventas_SellIn!$J$2:$J$800,Ventas_SellIn!$F$2:$F$800,$A27)) -> 28
A28: =Inicio!$E$10 -> Tradicional | B28: =IF($A28="","",SUMIFS(Ventas_SellIn!$L$2:$L$800,Ventas_SellIn!$F$2:$F$800,$A28)) -> 0 | C28: =IF($A28="","",SUMIFS(Ventas_SellIn!$J$2:$J$800,Ventas_SellIn!$F$2:$F$800,$A28)) -> 0
A29: =Inicio!$E$11 -> Ecommerce | B29: =IF($A29="","",SUMIFS(Ventas_SellIn!$L$2:$L$800,Ventas_SellIn!$F$2:$F$800,$A29)) -> 0 | C29: =IF($A29="","",SUMIFS(Ventas_SellIn!$J$2:$J$800,Ventas_SellIn!$F$2:$F$800,$A29)) -> 0
A30: =Inicio!$E$12 -> Corporativo | B30: =IF($A30="","",SUMIFS(Ventas_SellIn!$L$2:$L$800,Ventas_SellIn!$F$2:$F$800,$A30)) -> 607254 | C30: =IF($A30="","",SUMIFS(Ventas_SellIn!$J$2:$J$800,Ventas_SellIn!$F$2:$F$800,$A30)) -> 46
A31: =Inicio!$E$13 -> Distribuidor | B31: =IF($A31="","",SUMIFS(Ventas_SellIn!$L$2:$L$800,Ventas_SellIn!$F$2:$F$800,$A31)) -> 0 | C31: =IF($A31="","",SUMIFS(Ventas_SellIn!$J$2:$J$800,Ventas_SellIn!$F$2:$F$800,$A31)) -> 0
A32: Tip: en Ventas_SellIn filtra la columna Fecha → Filtros de fecha → Entre… para ver el detalle.
A33: Reporte de ventas por rango de fechas
A34: Desde: | B34: 46023 | C34: Hasta: | D34: 46387
A35: Métrica | B35: Valor
A36: Venta NETA del rango (sin IVA) | B36: =SUMIFS(Ventas_SellIn!$L$2:$L$800,Ventas_SellIn!$B$2:$B$800,">="&$B$34,Ventas_SellIn!$B$2:$B$800,"<="&$D$34) -> 5894865
A37: Unidades (rango) | B37: =SUMIFS(Ventas_SellIn!$J$2:$J$800,Ventas_SellIn!$B$2:$B$800,">="&$B$34,Ventas_SellIn!$B$2:$B$800,"<="&$D$34) -> 629
A38: N° facturas/líneas | B38: =COUNTIFS(Ventas_SellIn!$B$2:$B$800,">="&$B$34,Ventas_SellIn!$B$2:$B$800,"<="&$D$34,Ventas_SellIn!$A$2:$A$800,"<>") -> 45
A39: Deuda del rango (con IVA) | B39: =SUMIFS(Ventas_SellIn!$R$2:$R$800,Ventas_SellIn!$B$2:$B$800,">="&$B$34,Ventas_SellIn!$B$2:$B$800,"<="&$D$34) -> 2688041.9
A41: Venta por canal en el rango
A42: Canal | B42: Venta neta | C42: Unidades
A43: =Inicio!$E$5 -> Retail | B43: =IF($A43="","",SUMIFS(Ventas_SellIn!$L$2:$L$800,Ventas_SellIn!$F$2:$F$800,$A43,Ventas_SellIn!$B$2:$B$800,">="&$B$34,Ventas_SellIn!$B$2:$B$800,"<="&$D$34)) -> 1006642 | C43: =IF($A43="","",SUMIFS(Ventas_SellIn!$J$2:$J$800,Ventas_SellIn!$F$2:$F$800,$A43,Ventas_SellIn!$B$2:$B$800,">="&$B$34,Ventas_SellIn!$B$2:$B$800,"<="&$D$34)) -> 102
A44: =Inicio!$E$6 -> Conveniencia | B44: =IF($A44="","",SUMIFS(Ventas_SellIn!$L$2:$L$800,Ventas_SellIn!$F$2:$F$800,$A44,Ventas_SellIn!$B$2:$B$800,">="&$B$34,Ventas_SellIn!$B$2:$B$800,"<="&$D$34)) -> 1713268 | C44: =IF($A44="","",SUMIFS(Ventas_SellIn!$J$2:$J$800,Ventas_SellIn!$F$2:$F$800,$A44,Ventas_SellIn!$B$2:$B$800,">="&$B$34,Ventas_SellIn!$B$2:$B$800,"<="&$D$34)) -> 143
...

Sheet Plan_Inventario
A1: Producto (SKU) | B1: Descripción | C1: Sell-in ventana | D1: Venta/día | E1: Stock objetivo | F1: Bodega (unid.) | G1: Bodega barras | H1: Reponer (barras) | I1: Estado | K1: ⚙ Configuración
A2: =IF(Maestro_SKU!A2="","",Maestro_SKU!A2) -> NUVA-BAR-BM-U-01 | B2: =IF(A2="","",IFERROR(VLOOKUP(A2,Maestro_SKU!$A$2:$P$500,2,FALSE),"")) -> Barra Berry Mix unidad | C2: =IF(A2="","",SUMIFS(Ventas_SellIn!$Y$2:$Y$800,Ventas_SellIn!$H$2:$H$800,A2,Ventas_SellIn!$B$2:$B$800,">="&TODAY()-cfg_VentanaDemanda)) -> 32 | D2: =IF(A2="","",C2/cfg_VentanaDemanda) -> 1.0666667 | E2: =IF(A2="","",ROUND(D2*cfg_DiasCobertura*(1+cfg_PctSeguridad),0)) -> 38 | F2: 20 | G2: =IF(A2="","",IF(F2="",0,F2*IFERROR(VLOOKUP(A2,Maestro_SKU!$A$2:$P$500,12,FALSE),1))) -> 20 | H2: =IF(A2="","",MAX(E2-G2,0)) -> 18 | I2: =IF(A2="","",IF(F2="","Falta bodega",IF(G2>=E2,"OK",IF(G2>=E2*0.6,"Ajustado","Reponer")))) -> Reponer
A3: =IF(Maestro_SKU!A3="","",Maestro_SKU!A3) -> NUVA-BAR-PB-U-01 | B3: =IF(A3="","",IFERROR(VLOOKUP(A3,Maestro_SKU!$A$2:$P$500,2,FALSE),"")) -> Barra Peanut Boost unidad | C3: =IF(A3="","",SUMIFS(Ventas_SellIn!$Y$2:$Y$800,Ventas_SellIn!$H$2:$H$800,A3,Ventas_SellIn!$B$2:$B$800,">="&TODAY()-cfg_VentanaDemanda)) -> 32 | D3: =IF(A3="","",C3/cfg_VentanaDemanda) -> 1.0666667 | E3: =IF(A3="","",ROUND(D3*cfg_DiasCobertura*(1+cfg_PctSeguridad),0)) -> 38 | F3: 20 | G3: =IF(A3="","",IF(F3="",0,F3*IFERROR(VLOOKUP(A3,Maestro_SKU!$A$2:$P$500,12,FALSE),1))) -> 20 | H3: =IF(A3="","",MAX(E3-G3,0)) -> 18 | I3: =IF(A3="","",IF(F3="","Falta bodega",IF(G3>=E3,"OK",IF(G3>=E3*0.6,"Ajustado","Reponer")))) -> Reponer
A4: =IF(Maestro_SKU!A4="","",Maestro_SKU!A4) -> NUVA-BAR-CC-U-01 | B4: =IF(A4="","",IFERROR(VLOOKUP(A4,Maestro_SKU!$A$2:$P$500,2,FALSE),"")) -> Barra Cacao Crispy unidad | C4: =IF(A4="","",SUMIFS(Ventas_SellIn!$Y$2:$Y$800,Ventas_SellIn!$H$2:$H$800,A4,Ventas_SellIn!$B$2:$B$800,">="&TODAY()-cfg_VentanaDemanda)) -> 32 | D4: =IF(A4="","",C4/cfg_VentanaDemanda) -> 1.0666667 | E4: =IF(A4="","",ROUND(D4*cfg_DiasCobertura*(1+cfg_PctSeguridad),0)) -> 38 | F4: 20 | G4: =IF(A4="","",IF(F4="",0,F4*IFERROR(VLOOKUP(A4,Maestro_SKU!$A$2:$P$500,12,FALSE),1))) -> 20 | H4: =IF(A4="","",MAX(E4-G4,0)) -> 18 | I4: =IF(A4="","",IF(F4="","Falta bodega",IF(G4>=E4,"OK",IF(G4>=E4*0.6,"Ajustado","Reponer")))) -> Reponer
A5: =IF(Maestro_SKU!A5="","",Maestro_SKU!A5) -> NUVA-BAR-BM-BX-04 | B5: =IF(A5="","",IFERROR(VLOOKUP(A5,Maestro_SKU!$A$2:$P$500,2,FALSE),"")) -> Estuche Berry Mix 4 unidades | C5: =IF(A5="","",SUMIFS(Ventas_SellIn!$Y$2:$Y$800,Ventas_SellIn!$H$2:$H$800,A5,Ventas_SellIn!$B$2:$B$800,">="&TODAY()-cfg_VentanaDemanda)) -> 80 | D5: =IF(A5="","",C5/cfg_VentanaDemanda) -> 2.6666667 | E5: =IF(A5="","",ROUND(D5*cfg_DiasCobertura*(1+cfg_PctSeguridad),0)) -> 96 | F5: 20 | G5: =IF(A5="","",IF(F5="",0,F5*IFERROR(VLOOKUP(A5,Maestro_SKU!$A$2:$P$500,12,FALSE),1))) -> 80 | H5: =IF(A5="","",MAX(E5-G5,0)) -> 16 | I5: =IF(A5="","",IF(F5="","Falta bodega",IF(G5>=E5,"OK",IF(G5>=E5*0.6,"Ajustado","Reponer")))) -> Ajustado
A6: =IF(Maestro_SKU!A6="","",Maestro_SKU!A6) -> NUVA-BAR-PB-BX-04 | B6: =IF(A6="","",IFERROR(VLOOKUP(A6,Maestro_SKU!$A$2:$P$500,2,FALSE),"")) -> Estuche Peanut Boost 4 unidades | C6: =IF(A6="","",SUMIFS(Ventas_SellIn!$Y$2:$Y$800,Ventas_SellIn!$H$2:$H$800,A6,Ventas_SellIn!$B$2:$B$800,">="&TODAY()-cfg_VentanaDemanda)) -> 76 | D6: =IF(A6="","",C6/cfg_VentanaDemanda) -> 2.5333333 | E6: =IF(A6="","",ROUND(D6*cfg_DiasCobertura*(1+cfg_PctSeguridad),0)) -> 91 | F6: 20 | G6: =IF(A6="","",IF(F6="",0,F6*IFERROR(VLOOKUP(A6,Maestro_SKU!$A$2:$P$500,12,FALSE),1))) -> 80 | H6: =IF(A6="","",MAX(E6-G6,0)) -> 11 | I6: =IF(A6="","",IF(F6="","Falta bodega",IF(G6>=E6,"OK",IF(G6>=E6*0.6,"Ajustado","Reponer")))) -> Ajustado
A7: =IF(Maestro_SKU!A7="","",Maestro_SKU!A7) -> NUVA-BAR-CC-BX-04 | B7: =IF(A7="","",IFERROR(VLOOKUP(A7,Maestro_SKU!$A$2:$P$500,2,FALSE),"")) -> Estuche Cacao Crispy 4 unidades | C7: =IF(A7="","",SUMIFS(Ventas_SellIn!$Y$2:$Y$800,Ventas_SellIn!$H$2:$H$800,A7,Ventas_SellIn!$B$2:$B$800,">="&TODAY()-cfg_VentanaDemanda)) -> 160 | D7: =IF(A7="","",C7/cfg_VentanaDemanda) -> 5.3333333 | E7: =IF(A7="","",ROUND(D7*cfg_DiasCobertura*(1+cfg_PctSeguridad),0)) -> 192 | F7: 100 | G7: =IF(A7="","",IF(F7="",0,F7*IFERROR(VLOOKUP(A7,Maestro_SKU!$A$2:$P$500,12,FALSE),1))) -> 400 | H7: =IF(A7="","",MAX(E7-G7,0)) -> 0 | I7: =IF(A7="","",IF(F7="","Falta bodega",IF(G7>=E7,"OK",IF(G7>=E7*0.6,"Ajustado","Reponer")))) -> OK
A8: =IF(Maestro_SKU!A8="","",Maestro_SKU!A8) -> NUVA-BAR-BM-CS-24 | B8: =IF(A8="","",IFERROR(VLOOKUP(A8,Maestro_SKU!$A$2:$P$500,2,FALSE),"")) -> Caja master Berry Mix 24 unidades | C8: =IF(A8="","",SUMIFS(Ventas_SellIn!$Y$2:$Y$800,Ventas_SellIn!$H$2:$H$800,A8,Ventas_SellIn!$B$2:$B$800,">="&TODAY()-cfg_VentanaDemanda)) -> 1056 | D8: =IF(A8="","",C8/cfg_VentanaDemanda) -> 35.2 | E8: =IF(A8="","",ROUND(D8*cfg_DiasCobertura*(1+cfg_PctSeguridad),0)) -> 1267 | F8: 50 | G8: =IF(A8="","",IF(F8="",0,F8*IFERROR(VLOOKUP(A8,Maestro_SKU!$A$2:$P$500,12,FALSE),1))) -> 1200 | H8: =IF(A8="","",MAX(E8-G8,0)) -> 67 | I8: =IF(A8="","",IF(F8="","Falta bodega",IF(G8>=E8,"OK",IF(G8>=E8*0.6,"Ajustado","Reponer")))) -> Ajustado
A9: =IF(Maestro_SKU!A9="","",Maestro_SKU!A9) -> NUVA-BAR-PB-CS-24 | B9: =IF(A9="","",IFERROR(VLOOKUP(A9,Maestro_SKU!$A$2:$P$500,2,FALSE),"")) -> Caja master Peanut Boost 24 unidades | C9: =IF(A9="","",SUMIFS(Ventas_SellIn!$Y$2:$Y$800,Ventas_SellIn!$H$2:$H$800,A9,Ventas_SellIn!$B$2:$B$800,">="&TODAY()-cfg_VentanaDemanda)) -> 1200 | D9: =IF(A9="","",C9/cfg_VentanaDemanda) -> 40 | E9: =IF(A9="","",ROUND(D9*cfg_DiasCobertura*(1+cfg_PctSeguridad),0)) -> 1440 | F9: 20 | G9: =IF(A9="","",IF(F9="",0,F9*IFERROR(VLOOKUP(A9,Maestro_SKU!$A$2:$P$500,12,FALSE),1))) -> 480 | H9: =IF(A9="","",MAX(E9-G9,0)) -> 960 | I9: =IF(A9="","",IF(F9="","Falta bodega",IF(G9>=E9,"OK",IF(G9>=E9*0.6,"Ajustado","Reponer")))) -> Reponer
A10: =IF(Maestro_SKU!A10="","",Maestro_SKU!A10) -> NUVA-BAR-CC-CS-24 | B10: =IF(A10="","",IFERROR(VLOOKUP(A10,Maestro_SKU!$A$2:$P$500,2,FALSE),"")) -> Caja master Cacao Crispy 24 unidades | C10: =IF(A10="","",SUMIFS(Ventas_SellIn!$Y$2:$Y$800,Ventas_SellIn!$H$2:$H$800,A10,Ventas_SellIn!$B$2:$B$800,">="&TODAY()-cfg_VentanaDemanda)) -> 912 | D10: =IF(A10="","",C10/cfg_VentanaDemanda) -> 30.4 | E10: =IF(A10="","",ROUND(D10*cfg_DiasCobertura*(1+cfg_PctSeguridad),0)) -> 1094 | F10: 20 | G10: =IF(A10="","",IF(F10="",0,F10*IFERROR(VLOOKUP(A10,Maestro_SKU!$A$2:$P$500,12,FALSE),1))) -> 480 | H10: =IF(A10="","",MAX(E10-G10,0)) -> 614 | I10: =IF(A10="","",IF(F10="","Falta bodega",IF(G10>=E10,"OK",IF(G10>=E10*0.6,"Ajustado","Reponer")))) -> Reponer
A11: =IF(Maestro_SKU!A11="","",Maestro_SKU!A11) -> NUVA-BAR-BM-CS-60 | B11: =IF(A11="","",IFERROR(VLOOKUP(A11,Maestro_SKU!$A$2:$P$500,2,FALSE),"")) -> Caja master Berry Mix 15x4 unidades | C11: =IF(A11="","",SUMIFS(Ventas_SellIn!$Y$2:$Y$800,Ventas_SellIn!$H$2:$H$800,A11,Ventas_SellIn!$B$2:$B$800,">="&TODAY()-cfg_VentanaDemanda)) -> 0 | D11: =IF(A11="","",C11/cfg_VentanaDemanda) -> 0 | E11: =IF(A11="","",ROUND(D11*cfg_DiasCobertura*(1+cfg_PctSeguridad),0)) -> 0 | F11: 20 | G11: =IF(A11="","",IF(F11="",0,F11*IFERROR(VLOOKUP(A11,Maestro_SKU!$A$2:$P$500,12,FALSE),1))) -> 1200 | H11: =IF(A11="","",MAX(E11-G11,0)) -> 0 | I11: =IF(A11="","",IF(F11="","Falta bodega",IF(G11>=E11,"OK",IF(G11>=E11*0.6,"Ajustado","Reponer")))) -> OK
A12: =IF(Maestro_SKU!A12="","",Maestro_SKU!A12) -> NUVA-BAR-PB-CS-60 | B12: =IF(A12="","",IFERROR(VLOOKUP(A12,Maestro_SKU!$A$2:$P$500,2,FALSE),"")) -> Caja master Peanut Boost 15x4 unidades | C12: =IF(A12="","",SUMIFS(Ventas_SellIn!$Y$2:$Y$800,Ventas_SellIn!$H$2:$H$800,A12,Ventas_SellIn!$B$2:$B$800,">="&TODAY()-cfg_VentanaDemanda)) -> 0 | D12: =IF(A12="","",C12/cfg_VentanaDemanda) -> 0 | E12: =IF(A12="","",ROUND(D12*cfg_DiasCobertura*(1+cfg_PctSeguridad),0)) -> 0 | F12: 20 | G12: =IF(A12="","",IF(F12="",0,F12*IFERROR(VLOOKUP(A12,Maestro_SKU!$A$2:$P$500,12,FALSE),1))) -> 1200 | H12: =IF(A12="","",MAX(E12-G12,0)) -> 0 | I12: =IF(A12="","",IF(F12="","Falta bodega",IF(G12>=E12,"OK",IF(G12>=E12*0.6,"Ajustado","Reponer")))) -> OK
A13: =IF(Maestro_SKU!A13="","",Maestro_SKU!A13) -> NUVA-BAR-CC-CS-60 | B13: =IF(A13="","",IFERROR(VLOOKUP(A13,Maestro_SKU!$A$2:$P$500,2,FALSE),"")) -> Caja master Cacao Crispy 15x4 unidades | C13: =IF(A13="","",SUMIFS(Ventas_SellIn!$Y$2:$Y$800,Ventas_SellIn!$H$2:$H$800,A13,Ventas_SellIn!$B$2:$B$800,">="&TODAY()-cfg_VentanaDemanda)) -> 0 | D13: =IF(A13="","",C13/cfg_VentanaDemanda) -> 0 | E13: =IF(A13="","",ROUND(D13*cfg_DiasCobertura*(1+cfg_PctSeguridad),0)) -> 0 | F13: 20 | G13: =IF(A13="","",IF(F13="",0,F13*IFERROR(VLOOKUP(A13,Maestro_SKU!$A$2:$P$500,12,FALSE),1))) -> 1200 | H13: =IF(A13="","",MAX(E13-G13,0)) -> 0 | I13: =IF(A13="","",IF(F13="","Falta bodega",IF(G13>=E13,"OK",IF(G13>=E13*0.6,"Ajustado","Reponer")))) -> OK
A14: =IF(Maestro_SKU!A14="","",Maestro_SKU!A14) | B14: =IF(A14="","",IFERROR(VLOOKUP(A14,Maestro_SKU!$A$2:$P$500,2,FALSE),"")) | C14: =IF(A14="","",SUMIFS(Ventas_SellIn!$Y$2:$Y$800,Ventas_SellIn!$H$2:$H$800,A14,Ventas_SellIn!$B$2:$B$800,">="&TODAY()-cfg_VentanaDemanda)) | D14: =IF(A14="","",C14/cfg_VentanaDemanda) | E14: =IF(A14="","",ROUND(D14*cfg_DiasCobertura*(1+cfg_PctSeguridad),0)) | G14: =IF(A14="","",IF(F14="",0,F14*IFERROR(VLOOKUP(A14,Maestro_SKU!$A$2:$P$500,12,FALSE),1))) | H14: =IF(A14="","",MAX(E14-G14,0)) | I14: =IF(A14="","",IF(F14="","Falta bodega",IF(G14>=E14,"OK",IF(G14>=E14*0.6,"Ajustado","Reponer"))))
A15: =IF(Maestro_SKU!A15="","",Maestro_SKU!A15) | B15: =IF(A15="","",IFERROR(VLOOKUP(A15,Maestro_SKU!$A$2:$P$500,2,FALSE),"")) | C15: =IF(A15="","",SUMIFS(Ventas_SellIn!$Y$2:$Y$800,Ventas_SellIn!$H$2:$H$800,A15,Ventas_SellIn!$B$2:$B$800,">="&TODAY()-cfg_VentanaDemanda)) | D15: =IF(A15="","",C15/cfg_VentanaDemanda) | E15: =IF(A15="","",ROUND(D15*cfg_DiasCobertura*(1+cfg_PctSeguridad),0)) | G15: =IF(A15="","",IF(F15="",0,F15*IFERROR(VLOOKUP(A15,Maestro_SKU!$A$2:$P$500,12,FALSE),1))) | H15: =IF(A15="","",MAX(E15-G15,0)) | I15: =IF(A15="","",IF(F15="","Falta bodega",IF(G15>=E15,"OK",IF(G15>=E15*0.6,"Ajustado","Reponer"))))
A16: =IF(Maestro_SKU!A16="","",Maestro_SKU!A16) | B16: =IF(A16="","",IFERROR(VLOOKUP(A16,Maestro_SKU!$A$2:$P$500,2,FALSE),"")) | C16: =IF(A16="","",SUMIFS(Ventas_SellIn!$Y$2:$Y$800,Ventas_SellIn!$H$2:$H$800,A16,Ventas_SellIn!$B$2:$B$800,">="&TODAY()-cfg_VentanaDemanda)) | D16: =IF(A16="","",C16/cfg_VentanaDemanda) | E16: =IF(A16="","",ROUND(D16*cfg_DiasCobertura*(1+cfg_PctSeguridad),0)) | G16: =IF(A16="","",IF(F16="",0,F16*IFERROR(VLOOKUP(A16,Maestro_SKU!$A$2:$P$500,12,FALSE),1))) | H16: =IF(A16="","",MAX(E16-G16,0)) | I16: =IF(A16="","",IF(F16="","Falta bodega",IF(G16>=E16,"OK",IF(G16>=E16*0.6,"Ajustado","Reponer"))))
A17: =IF(Maestro_SKU!A17="","",Maestro_SKU!A17) | B17: =IF(A17="","",IFERROR(VLOOKUP(A17,Maestro_SKU!$A$2:$P$500,2,FALSE),"")) | C17: =IF(A17="","",SUMIFS(Ventas_SellIn!$Y$2:$Y$800,Ventas_SellIn!$H$2:$H$800,A17,Ventas_SellIn!$B$2:$B$800,">="&TODAY()-cfg_VentanaDemanda)) | D17: =IF(A17="","",C17/cfg_VentanaDemanda) | E17: =IF(A17="","",ROUND(D17*cfg_DiasCobertura*(1+cfg_PctSeguridad),0)) | G17: =IF(A17="","",IF(F17="",0,F17*IFERROR(VLOOKUP(A17,Maestro_SKU!$A$2:$P$500,12,FALSE),1))) | H17: =IF(A17="","",MAX(E17-G17,0)) | I17: =IF(A17="","",IF(F17="","Falta bodega",IF(G17>=E17,"OK",IF(G17>=E17*0.6,"Ajustado","Reponer"))))
A18: =IF(Maestro_SKU!A18="","",Maestro_SKU!A18) | B18: =IF(A18="","",IFERROR(VLOOKUP(A18,Maestro_SKU!$A$2:$P$500,2,FALSE),"")) | C18: =IF(A18="","",SUMIFS(Ventas_SellIn!$Y$2:$Y$800,Ventas_SellIn!$H$2:$H$800,A18,Ventas_SellIn!$B$2:$B$800,">="&TODAY()-cfg_VentanaDemanda)) | D18: =IF(A18="","",C18/cfg_VentanaDemanda) | E18: =IF(A18="","",ROUND(D18*cfg_DiasCobertura*(1+cfg_PctSeguridad),0)) | G18: =IF(A18="","",IF(F18="",0,F18*IFERROR(VLOOKUP(A18,Maestro_SKU!$A$2:$P$500,12,FALSE),1))) | H18: =IF(A18="","",MAX(E18-G18,0)) | I18: =IF(A18="","",IF(F18="","Falta bodega",IF(G18>=E18,"OK",IF(G18>=E18*0.6,"Ajustado","Reponer"))))
A19: =IF(Maestro_SKU!A19="","",Maestro_SKU!A19) | B19: =IF(A19="","",IFERROR(VLOOKUP(A19,Maestro_SKU!$A$2:$P$500,2,FALSE),"")) | C19: =IF(A19="","",SUMIFS(Ventas_SellIn!$Y$2:$Y$800,Ventas_SellIn!$H$2:$H$800,A19,Ventas_SellIn!$B$2:$B$800,">="&TODAY()-cfg_VentanaDemanda)) | D19: =IF(A19="","",C19/cfg_VentanaDemanda) | E19: =IF(A19="","",ROUND(D19*cfg_DiasCobertura*(1+cfg_PctSeguridad),0)) | G19: =IF(A19="","",IF(F19="",0,F19*IFERROR(VLOOKUP(A19,Maestro_SKU!$A$2:$P$500,12,FALSE),1))) | H19: =IF(A19="","",MAX(E19-G19,0)) | I19: =IF(A19="","",IF(F19="","Falta bodega",IF(G19>=E19,"OK",IF(G19>=E19*0.6,"Ajustado","Reponer"))))
A20: =IF(Maestro_SKU!A20="","",Maestro_SKU!A20) | B20: =IF(A20="","",IFERROR(VLOOKUP(A20,Maestro_SKU!$A$2:$P$500,2,FALSE),"")) | C20: =IF(A20="","",SUMIFS(Ventas_SellIn!$Y$2:$Y$800,Ventas_SellIn!$H$2:$H$800,A20,Ventas_SellIn!$B$2:$B$800,">="&TODAY()-cfg_VentanaDemanda)) | D20: =IF(A20="","",C20/cfg_VentanaDemanda) | E20: =IF(A20="","",ROUND(D20*cfg_DiasCobertura*(1+cfg_PctSeguridad),0)) | G20: =IF(A20="","",IF(F20="",0,F20*IFERROR(VLOOKUP(A20,Maestro_SKU!$A$2:$P$500,12,FALSE),1))) | H20: =IF(A20="","",MAX(E20-G20,0)) | I20: =IF(A20="","",IF(F20="","Falta bodega",IF(G20>=E20,"OK",IF(G20>=E20*0.6,"Ajustado","Reponer"))))
A21: =IF(Maestro_SKU!A21="","",Maestro_SKU!A21) | B21: =IF(A21="","",IFERROR(VLOOKUP(A21,Maestro_SKU!$A$2:$P$500,2,FALSE),"")) | C21: =IF(A21="","",SUMIFS(Ventas_SellIn!$Y$2:$Y$800,Ventas_SellIn!$H$2:$H$800,A21,Ventas_SellIn!$B$2:$B$800,">="&TODAY()-cfg_VentanaDemanda)) | D21: =IF(A21="","",C21/cfg_VentanaDemanda) | E21: =IF(A21="","",ROUND(D21*cfg_DiasCobertura*(1+cfg_PctSeguridad),0)) | G21: =IF(A21="","",IF(F21="",0,F21*IFERROR(VLOOKUP(A21,Maestro_SKU!$A$2:$P$500,12,FALSE),1))) | H21: =IF(A21="","",MAX(E21-G21,0)) | I21: =IF(A21="","",IF(F21="","Falta bodega",IF(G21>=E21,"OK",IF(G21>=E21*0.6,"Ajustado","Reponer"))))
A22: =IF(Maestro_SKU!A22="","",Maestro_SKU!A22) | B22: =IF(A22="","",IFERROR(VLOOKUP(A22,Maestro_SKU!$A$2:$P$500,2,FALSE),"")) | C22: =IF(A22="","",SUMIFS(Ventas_SellIn!$Y$2:$Y$800,Ventas_SellIn!$H$2:$H$800,A22,Ventas_SellIn!$B$2:$B$800,">="&TODAY()-cfg_VentanaDemanda)) | D22: =IF(A22="","",C22/cfg_VentanaDemanda) | E22: =IF(A22="","",ROUND(D22*cfg_DiasCobertura*(1+cfg_PctSeguridad),0)) | G22: =IF(A22="","",IF(F22="",0,F22*IFERROR(VLOOKUP(A22,Maestro_SKU!$A$2:$P$500,12,FALSE),1))) | H22: =IF(A22="","",MAX(E22-G22,0)) | I22: =IF(A22="","",IF(F22="","Falta bodega",IF(G22>=E22,"OK",IF(G22>=E22*0.6,"Ajustado","Reponer"))))
A23: =IF(Maestro_SKU!A23="","",Maestro_SKU!A23) | B23: =IF(A23="","",IFERROR(VLOOKUP(A23,Maestro_SKU!$A$2:$P$500,2,FALSE),"")) | C23: =IF(A23="","",SUMIFS(Ventas_SellIn!$Y$2:$Y$800,Ventas_SellIn!$H$2:$H$800,A23,Ventas_SellIn!$B$2:$B$800,">="&TODAY()-cfg_VentanaDemanda)) | D23: =IF(A23="","",C23/cfg_VentanaDemanda) | E23: =IF(A23="","",ROUND(D23*cfg_DiasCobertura*(1+cfg_PctSeguridad),0)) | G23: =IF(A23="","",IF(F23="",0,F23*IFERROR(VLOOKUP(A23,Maestro_SKU!$A$2:$P$500,12,FALSE),1))) | H23: =IF(A23="","",MAX(E23-G23,0)) | I23: =IF(A23="","",IF(F23="","Falta bodega",IF(G23>=E23,"OK",IF(G23>=E23*0.6,"Ajustado","Reponer"))))
A24: =IF(Maestro_SKU!A24="","",Maestro_SKU!A24) | B24: =IF(A24="","",IFERROR(VLOOKUP(A24,Maestro_SKU!$A$2:$P$500,2,FALSE),"")) | C24: =IF(A24="","",SUMIFS(Ventas_SellIn!$Y$2:$Y$800,Ventas_SellIn!$H$2:$H$800,A24,Ventas_SellIn!$B$2:$B$800,">="&TODAY()-cfg_VentanaDemanda)) | D24: =IF(A24="","",C24/cfg_VentanaDemanda) | E24: =IF(A24="","",ROUND(D24*cfg_DiasCobertura*(1+cfg_PctSeguridad),0)) | G24: =IF(A24="","",IF(F24="",0,F24*IFERROR(VLOOKUP(A24,Maestro_SKU!$A$2:$P$500,12,FALSE),1))) | H24: =IF(A24="","",MAX(E24-G24,0)) | I24: =IF(A24="","",IF(F24="","Falta bodega",IF(G24>=E24,"OK",IF(G24>=E24*0.6,"Ajustado","Reponer"))))
A25: =IF(Maestro_SKU!A25="","",Maestro_SKU!A25) | B25: =IF(A25="","",IFERROR(VLOOKUP(A25,Maestro_SKU!$A$2:$P$500,2,FALSE),"")) | C25: =IF(A25="","",SUMIFS(Ventas_SellIn!$Y$2:$Y$800,Ventas_SellIn!$H$2:$H$800,A25,Ventas_SellIn!$B$2:$B$800,">="&TODAY()-cfg_VentanaDemanda)) | D25: =IF(A25="","",C25/cfg_VentanaDemanda) | E25: =IF(A25="","",ROUND(D25*cfg_DiasCobertura*(1+cfg_PctSeguridad),0)) | G25: =IF(A25="","",IF(F25="",0,F25*IFERROR(VLOOKUP(A25,Maestro_SKU!$A$2:$P$500,12,FALSE),1))) | H25: =IF(A25="","",MAX(E25-G25,0)) | I25: =IF(A25="","",IF(F25="","Falta bodega",IF(G25>=E25,"OK",IF(G25>=E25*0.6,"Ajustado","Reponer"))))
... A81: =IF(Maestro_SKU!A81="","",Maestro_SKU!A81) | B81: =IF(A81="","",IFERROR(VLOOKUP(A81,Maestro_SKU!$A$2:$P$500,2,FALSE),"")) | C81: =IF(A81="","",SUMIFS(Ventas_SellIn!$Y$2:$Y$800,Ventas_SellIn!$H$2:$H$800,A81,Ventas_SellIn!$B$2:$B$800,">="&TODAY()-cfg_VentanaDemanda)) | D81: =IF(A81="","",C81/cfg_VentanaDemanda) | E81: =IF(A81="","",ROUND(D81*cfg_DiasCobertura*(1+cfg_PctSeguridad),0)) | G81: =IF(A81="","",IF(F81="",0,F81*IFERROR(VLOOKUP(A81,Maestro_SKU!$A$2:$P$500,12,FALSE),1))) | H81: =IF(A81="","",MAX(E81-G81,0)) | I81: =IF(A81="","",IF(F81="","Falta bodega",IF(G81>=E81,"OK",IF(G81>=E81*0.6,"Ajustado","Reponer"))))

Sheet Bodegas
A1: Bodega_ID | B1: Cliente | C1: Nombre bodega | D1: Dirección | E1: Sell-in acum. (barras) | F1: Sell-out acum. (barras) | G1: Stock en salas (barras) | H1: Estimado en bodega (barras)
A2: BOD-001 | B2: Jumbo | C2: Bodega Cencosud | E2: =IF($B2="","",SUMIFS(Ventas_SellIn!$Y$2:$Y$800,Ventas_SellIn!$E$2:$E$800,$B2)) -> 1350 | F2: =IF($B2="","",SUMIFS(SellOut_Jumbo!$O$2:$O$800,SellOut_Jumbo!$B$2:$B$800,$B2)) -> 243 | G2: =IF($B2="","",SUMIFS(Stock_PDV!$H$2:$H$800,Stock_PDV!$B$2:$B$800,$B2)) -> 188 | H2: =IF($B2="","",E2-F2-G2) -> 919
E3: =IF($B3="","",SUMIFS(Ventas_SellIn!$Y$2:$Y$800,Ventas_SellIn!$E$2:$E$800,$B3)) | F3: =IF($B3="","",SUMIFS(SellOut_Jumbo!$O$2:$O$800,SellOut_Jumbo!$B$2:$B$800,$B3)) | G3: =IF($B3="","",SUMIFS(Stock_PDV!$H$2:$H$800,Stock_PDV!$B$2:$B$800,$B3)) | H3: =IF($B3="","",E3-F3-G3)
E4: =IF($B4="","",SUMIFS(Ventas_SellIn!$Y$2:$Y$800,Ventas_SellIn!$E$2:$E$800,$B4)) | F4: =IF($B4="","",SUMIFS(SellOut_Jumbo!$O$2:$O$800,SellOut_Jumbo!$B$2:$B$800,$B4)) | G4: =IF($B4="","",SUMIFS(Stock_PDV!$H$2:$H$800,Stock_PDV!$B$2:$B$800,$B4)) | H4: =IF($B4="","",E4-F4-G4)
E5: =IF($B5="","",SUMIFS(Ventas_SellIn!$Y$2:$Y$800,Ventas_SellIn!$E$2:$E$800,$B5)) | F5: =IF($B5="","",SUMIFS(SellOut_Jumbo!$O$2:$O$800,SellOut_Jumbo!$B$2:$B$800,$B5)) | G5: =IF($B5="","",SUMIFS(Stock_PDV!$H$2:$H$800,Stock_PDV!$B$2:$B$800,$B5)) | H5: =IF($B5="","",E5-F5-G5)
E6: =IF($B6="","",SUMIFS(Ventas_SellIn!$Y$2:$Y$800,Ventas_SellIn!$E$2:$E$800,$B6)) | F6: =IF($B6="","",SUMIFS(SellOut_Jumbo!$O$2:$O$800,SellOut_Jumbo!$B$2:$B$800,$B6)) | G6: =IF($B6="","",SUMIFS(Stock_PDV!$H$2:$H$800,Stock_PDV!$B$2:$B$800,$B6)) | H6: =IF($B6="","",E6-F6-G6)
E7: =IF($B7="","",SUMIFS(Ventas_SellIn!$Y$2:$Y$800,Ventas_SellIn!$E$2:$E$800,$B7)) | F7: =IF($B7="","",SUMIFS(SellOut_Jumbo!$O$2:$O$800,SellOut_Jumbo!$B$2:$B$800,$B7)) | G7: =IF($B7="","",SUMIFS(Stock_PDV!$H$2:$H$800,Stock_PDV!$B$2:$B$800,$B7)) | H7: =IF($B7="","",E7-F7-G7)
E8: =IF($B8="","",SUMIFS(Ventas_SellIn!$Y$2:$Y$800,Ventas_SellIn!$E$2:$E$800,$B8)) | F8: =IF($B8="","",SUMIFS(SellOut_Jumbo!$O$2:$O$800,SellOut_Jumbo!$B$2:$B$800,$B8)) | G8: =IF($B8="","",SUMIFS(Stock_PDV!$H$2:$H$800,Stock_PDV!$B$2:$B$800,$B8)) | H8: =IF($B8="","",E8-F8-G8)
E9: =IF($B9="","",SUMIFS(Ventas_SellIn!$Y$2:$Y$800,Ventas_SellIn!$E$2:$E$800,$B9)) | F9: =IF($B9="","",SUMIFS(SellOut_Jumbo!$O$2:$O$800,SellOut_Jumbo!$B$2:$B$800,$B9)) | G9: =IF($B9="","",SUMIFS(Stock_PDV!$H$2:$H$800,Stock_PDV!$B$2:$B$800,$B9)) | H9: =IF($B9="","",E9-F9-G9)
E10: =IF($B10="","",SUMIFS(Ventas_SellIn!$Y$2:$Y$800,Ventas_SellIn!$E$2:$E$800,$B10)) | F10: =IF($B10="","",SUMIFS(SellOut_Jumbo!$O$2:$O$800,SellOut_Jumbo!$B$2:$B$800,$B10)) | G10: =IF($B10="","",SUMIFS(Stock_PDV!$H$2:$H$800,Stock_PDV!$B$2:$B$800,$B10)) | H10: =IF($B10="","",E10-F10-G10)
E11: =IF($B11="","",SUMIFS(Ventas_SellIn!$Y$2:$Y$800,Ventas_SellIn!$E$2:$E$800,$B11)) | F11: =IF($B11="","",SUMIFS(SellOut_Jumbo!$O$2:$O$800,SellOut_Jumbo!$B$2:$B$800,$B11)) | G11: =IF($B11="","",SUMIFS(Stock_PDV!$H$2:$H$800,Stock_PDV!$B$2:$B$800,$B11)) | H11: =IF($B11="","",E11-F11-G11)
E12: =IF($B12="","",SUMIFS(Ventas_SellIn!$Y$2:$Y$800,Ventas_SellIn!$E$2:$E$800,$B12)) | F12: =IF($B12="","",SUMIFS(SellOut_Jumbo!$O$2:$O$800,SellOut_Jumbo!$B$2:$B$800,$B12)) | G12: =IF($B12="","",SUMIFS(Stock_PDV!$H$2:$H$800,Stock_PDV!$B$2:$B$800,$B12)) | H12: =IF($B12="","",E12-F12-G12)
E13: =IF($B13="","",SUMIFS(Ventas_SellIn!$Y$2:$Y$800,Ventas_SellIn!$E$2:$E$800,$B13)) | F13: =IF($B13="","",SUMIFS(SellOut_Jumbo!$O$2:$O$800,SellOut_Jumbo!$B$2:$B$800,$B13)) | G13: =IF($B13="","",SUMIFS(Stock_PDV!$H$2:$H$800,Stock_PDV!$B$2:$B$800,$B13)) | H13: =IF($B13="","",E13-F13-G13)
E14: =IF($B14="","",SUMIFS(Ventas_SellIn!$Y$2:$Y$800,Ventas_SellIn!$E$2:$E$800,$B14)) | F14: =IF($B14="","",SUMIFS(SellOut_Jumbo!$O$2:$O$800,SellOut_Jumbo!$B$2:$B$800,$B14)) | G14: =IF($B14="","",SUMIFS(Stock_PDV!$H$2:$H$800,Stock_PDV!$B$2:$B$800,$B14)) | H14: =IF($B14="","",E14-F14-G14)
... E50: =IF($B50="","",SUMIFS(Ventas_SellIn!$Y$2:$Y$800,Ventas_SellIn!$E$2:$E$800,$B50)) | F50: =IF($B50="","",SUMIFS(SellOut_Jumbo!$O$2:$O$800,SellOut_Jumbo!$B$2:$B$800,$B50)) | G50: =IF($B50="","",SUMIFS(Stock_PDV!$H$2:$H$800,Stock_PDV!$B$2:$B$800,$B50)) | H50: =IF($B50="","",E50-F50-G50)

Sheet Cobertura
A1: PDV_ID | B1: Cliente | C1: Canal | D1: Punto de venta | E1: Frecuencia | F1: Última visita | G1: Días sin visita | H1: Estado visita | I1: Venta 30d NETA (sin IVA) | J1: Sell-out 30d unid. opcional | K1: Estado venta | L1: Facturas pendientes | M1: Deuda (con IVA) | N1: Estado pago | O1: Stock PDV barras | P1: Estado stock | Q1: Prioridad lunes | R1: Acción sugerida | S1: Rotación | T1: Dirección | V1: ⚙ Configuración
A2: =IF(Clientes_PDV!A2="","",Clientes_PDV!A2) -> PDV-001 | B2: =IF(A2="","",IFERROR(VLOOKUP(A2,Clientes_PDV!$A$2:$J$250,2,FALSE),"")) -> Jumbo | C2: =IF(A2="","",IFERROR(VLOOKUP(A2,Clientes_PDV!$A$2:$J$250,3,FALSE),"")) -> Retail | D2: =IF(A2="","",IFERROR(VLOOKUP(A2,Clientes_PDV!$A$2:$J$250,4,FALSE),"")) -> Jumbo Bilbao | E2: =IF(A2="","",IFERROR(VLOOKUP(A2,Clientes_PDV!$A$2:$J$250,7,FALSE),"")) -> Semanal | F2: =IF(A2="","",IFERROR(VLOOKUP(A2,Clientes_PDV!$A$2:$J$250,8,FALSE),"")) -> 46209 | G2: =IF(F2="","",TODAY()-F2) -> 4 | H2: =IF(A2="","",IF(F2="","Sin visita",IF(G2<=IFERROR(VLOOKUP(E2,Inicio!$A$24:$B$26,2,FALSE),0),"Vigente","Atrasado"))) -> Vigente | I2: =IF(A2="","",SUMIFS(Ventas_SellIn!$L$2:$L$800,Ventas_SellIn!$D$2:$D$800,A2,Ventas_SellIn!$B$2:$B$800,">="&TODAY()-Inicio!$B$14)) -> 411396 | J2: =IF(A2="","",SUMIFS(SellOut_Jumbo!$F$2:$F$800,SellOut_Jumbo!$C$2:$C$800,D2,SellOut_Jumbo!$A$2:$A$800,">="&TODAY()-Inicio!$B$14)) -> 41 | K2: =IF(A2="","",IF(I2=0,"Sin venta",IF(I2<Inicio!$B$15,"Venta baja","Venta OK"))) -> Venta baja | L2: =IF(A2="","",COUNTIFS(Ventas_SellIn!$D$2:$D$800,A2,Ventas_SellIn!$R$2:$R$800,">0")) -> 1 | M2: =IF(A2="","",SUMIFS(Ventas_SellIn!$R$2:$R$800,Ventas_SellIn!$D$2:$D$800,A2)) -> 1.4551915e-11 | N2: =IF(A2="","",IF(M2>=Inicio!$B$18,"Pendiente relevante",IF(M2>0,"Pendiente menor","Sin deuda"))) -> Pendiente menor | O2: =IF(A2="","",SUMIFS(Stock_PDV!$H$2:$H$800,Stock_PDV!$A$2:$A$800,A2)) -> 33 | P2: =IF(A2="","",IF(O2<=Inicio!$B$16,"Crítico",IF(O2<=Inicio!$B$17,"Observar","OK"))) -> OK | Q2: =IF(A2="","",IF(OR(H2="Atrasado",K2="Sin venta",N2="Pendiente relevante",P2="Crítico"),"Alta",IF(OR(K2="Venta baja",N2="Pendiente menor",P2="Observar"),"Media","Baja"))) -> Media | R2: =IF(A2="","",IF(Q2="Alta","Gestionar esta semana",IF(Q2="Media","Hacer seguimiento","Mantener"))) -> Hacer seguimiento | S2: =IF(A2="","",IF(I2=0,"Sin venta",IF(I2>=cfg_VentaAlta,"Alta",IF(I2<cfg_VentaBaja,"Baja","Media")))) -> Baja | T2: =IF(A2="","",IFERROR(VLOOKUP(A2,Clientes_PDV!$A$2:$K$250,11,FALSE),"")) -> 0
A3: =IF(Clientes_PDV!A3="","",Clientes_PDV!A3) -> PDV-002 | B3: =IF(A3="","",IFERROR(VLOOKUP(A3,Clientes_PDV!$A$2:$J$250,2,FALSE),"")) -> Jumbo | C3: =IF(A3="","",IFERROR(VLOOKUP(A3,Clientes_PDV!$A$2:$J$250,3,FALSE),"")) -> Retail | D3: =IF(A3="","",IFERROR(VLOOKUP(A3,Clientes_PDV!$A$2:$J$250,4,FALSE),"")) -> Jumbo Kennedy | E3: =IF(A3="","",IFERROR(VLOOKUP(A3,Clientes_PDV!$A$2:$J$250,7,FALSE),"")) -> Semanal | F3: =IF(A3="","",IFERROR(VLOOKUP(A3,Clientes_PDV!$A$2:$J$250,8,FALSE),"")) -> 46201 | G3: =IF(F3="","",TODAY()-F3) -> 12 | H3: =IF(A3="","",IF(F3="","Sin visita",IF(G3<=IFERROR(VLOOKUP(E3,Inicio!$A$24:$B$26,2,FALSE),0),"Vigente","Atrasado"))) -> Atrasado | I3: =IF(A3="","",SUMIFS(Ventas_SellIn!$L$2:$L$800,Ventas_SellIn!$D$2:$D$800,A3,Ventas_SellIn!$B$2:$B$800,">="&TODAY()-Inicio!$B$14)) -> 461000 | J3: =IF(A3="","",SUMIFS(SellOut_Jumbo!$F$2:$F$800,SellOut_Jumbo!$C$2:$C$800,D3,SellOut_Jumbo!$A$2:$A$800,">="&TODAY()-Inicio!$B$14)) -> 37 | K3: =IF(A3="","",IF(I3=0,"Sin venta",IF(I3<Inicio!$B$15,"Venta baja","Venta OK"))) -> Venta baja | L3: =IF(A3="","",COUNTIFS(Ventas_SellIn!$D$2:$D$800,A3,Ventas_SellIn!$R$2:$R$800,">0")) -> 0 | M3: =IF(A3="","",SUMIFS(Ventas_SellIn!$R$2:$R$800,Ventas_SellIn!$D$2:$D$800,A3)) -> 0 | N3: =IF(A3="","",IF(M3>=Inicio!$B$18,"Pendiente relevante",IF(M3>0,"Pendiente menor","Sin deuda"))) -> Sin deuda | O3: =IF(A3="","",SUMIFS(Stock_PDV!$H$2:$H$800,Stock_PDV!$A$2:$A$800,A3)) -> 0 | P3: =IF(A3="","",IF(O3<=Inicio!$B$16,"Crítico",IF(O3<=Inicio!$B$17,"Observar","OK"))) -> Crítico | Q3: =IF(A3="","",IF(OR(H3="Atrasado",K3="Sin venta",N3="Pendiente relevante",P3="Crítico"),"Alta",IF(OR(K3="Venta baja",N3="Pendiente menor",P3="Observar"),"Media","Baja"))) -> Alta | R3: =IF(A3="","",IF(Q3="Alta","Gestionar esta semana",IF(Q3="Media","Hacer seguimiento","Mantener"))) -> Gestionar esta semana | S3: =IF(A3="","",IF(I3=0,"Sin venta",IF(I3>=cfg_VentaAlta,"Alta",IF(I3<cfg_VentaBaja,"Baja","Media")))) -> Baja | T3: =IF(A3="","",IFERROR(VLOOKUP(A3,Clientes_PDV!$A$2:$K$250,11,FALSE),"")) -> 0
A4: =IF(Clientes_PDV!A4="","",Clientes_PDV!A4) -> PDV-003 | B4: =IF(A4="","",IFERROR(VLOOKUP(A4,Clientes_PDV!$A$2:$J$250,2,FALSE),"")) -> Jumbo | C4: =IF(A4="","",IFERROR(VLOOKUP(A4,Clientes_PDV!$A$2:$J$250,3,FALSE),"")) -> Retail | D4: =IF(A4="","",IFERROR(VLOOKUP(A4,Clientes_PDV!$A$2:$J$250,4,FALSE),"")) -> Jumbo La Reina | E4: =IF(A4="","",IFERROR(VLOOKUP(A4,Clientes_PDV!$A$2:$J$250,7,FALSE),"")) -> Quincenal | F4: =IF(A4="","",IFERROR(VLOOKUP(A4,Clientes_PDV!$A$2:$J$250,8,FALSE),"")) -> 46197 | G4: =IF(F4="","",TODAY()-F4) -> 16 | H4: =IF(A4="","",IF(F4="","Sin visita",IF(G4<=IFERROR(VLOOKUP(E4,Inicio!$A$24:$B$26,2,FALSE),0),"Vigente","Atrasado"))) -> Atrasado | I4: =IF(A4="","",SUMIFS(Ventas_SellIn!$L$2:$L$800,Ventas_SellIn!$D$2:$D$800,A4,Ventas_SellIn!$B$2:$B$800,">="&TODAY()-Inicio!$B$14)) -> 66220 | J4: =IF(A4="","",SUMIFS(SellOut_Jumbo!$F$2:$F$800,SellOut_Jumbo!$C$2:$C$800,D4,SellOut_Jumbo!$A$2:$A$800,">="&TODAY()-Inicio!$B$14)) -> 36 | K4: =IF(A4="","",IF(I4=0,"Sin venta",IF(I4<Inicio!$B$15,"Venta baja","Venta OK"))) -> Venta baja | L4: =IF(A4="","",COUNTIFS(Ventas_SellIn!$D$2:$D$800,A4,Ventas_SellIn!$R$2:$R$800,">0")) -> 1 | M4: =IF(A4="","",SUMIFS(Ventas_SellIn!$R$2:$R$800,Ventas_SellIn!$D$2:$D$800,A4)) -> 6076.14 | N4: =IF(A4="","",IF(M4>=Inicio!$B$18,"Pendiente relevante",IF(M4>0,"Pendiente menor","Sin deuda"))) -> Pendiente menor | O4: =IF(A4="","",SUMIFS(Stock_PDV!$H$2:$H$800,Stock_PDV!$A$2:$A$800,A4)) -> 155 | P4: =IF(A4="","",IF(O4<=Inicio!$B$16,"Crítico",IF(O4<=Inicio!$B$17,"Observar","OK"))) -> OK | Q4: =IF(A4="","",IF(OR(H4="Atrasado",K4="Sin venta",N4="Pendiente relevante",P4="Crítico"),"Alta",IF(OR(K4="Venta baja",N4="Pendiente menor",P4="Observar"),"Media","Baja"))) -> Alta | R4: =IF(A4="","",IF(Q4="Alta","Gestionar esta semana",IF(Q4="Media","Hacer seguimiento","Mantener"))) -> Gestionar esta semana | S4: =IF(A4="","",IF(I4=0,"Sin venta",IF(I4>=cfg_VentaAlta,"Alta",IF(I4<cfg_VentaBaja,"Baja","Media")))) -> Baja | T4: =IF(A4="","",IFERROR(VLOOKUP(A4,Clientes_PDV!$A$2:$K$250,11,FALSE),"")) -> 0
A5: =IF(Clientes_PDV!A5="","",Clientes_PDV!A5) -> PDV-004 | B5: =IF(A5="","",IFERROR(VLOOKUP(A5,Clientes_PDV!$A$2:$J$250,2,FALSE),"")) -> Get It | C5: =IF(A5="","",IFERROR(VLOOKUP(A5,Clientes_PDV!$A$2:$J$250,3,FALSE),"")) -> Conveniencia | D5: =IF(A5="","",IFERROR(VLOOKUP(A5,Clientes_PDV!$A$2:$J$250,4,FALSE),"")) -> Get It Apoquindo | E5: =IF(A5="","",IFERROR(VLOOKUP(A5,Clientes_PDV!$A$2:$J$250,7,FALSE),"")) -> Semanal | F5: =IF(A5="","",IFERROR(VLOOKUP(A5,Clientes_PDV!$A$2:$J$250,8,FALSE),"")) -> 46206 | G5: =IF(F5="","",TODAY()-F5) -> 7 | H5: =IF(A5="","",IF(F5="","Sin visita",IF(G5<=IFERROR(VLOOKUP(E5,Inicio!$A$24:$B$26,2,FALSE),0),"Vigente","Atrasado"))) -> Vigente | I5: =IF(A5="","",SUMIFS(Ventas_SellIn!$L$2:$L$800,Ventas_SellIn!$D$2:$D$800,A5,Ventas_SellIn!$B$2:$B$800,">="&TODAY()-Inicio!$B$14)) -> 368880 | J5: =IF(A5="","",SUMIFS(SellOut_Jumbo!$F$2:$F$800,SellOut_Jumbo!$C$2:$C$800,D5,SellOut_Jumbo!$A$2:$A$800,">="&TODAY()-Inicio!$B$14)) -> 0 | K5: =IF(A5="","",IF(I5=0,"Sin venta",IF(I5<Inicio!$B$15,"Venta baja","Venta OK"))) -> Venta baja | L5: =IF(A5="","",COUNTIFS(Ventas_SellIn!$D$2:$D$800,A5,Ventas_SellIn!$R$2:$R$800,">0")) -> 2 | M5: =IF(A5="","",SUMIFS(Ventas_SellIn!$R$2:$R$800,Ventas_SellIn!$D$2:$D$800,A5)) -> 27036.8 | N5: =IF(A5="","",IF(M5>=Inicio!$B$18,"Pendiente relevante",IF(M5>0,"Pendiente menor","Sin deuda"))) -> Pendiente menor | O5: =IF(A5="","",SUMIFS(Stock_PDV!$H$2:$H$800,Stock_PDV!$A$2:$A$800,A5)) -> 8 | P5: =IF(A5="","",IF(O5<=Inicio!$B$16,"Crítico",IF(O5<=Inicio!$B$17,"Observar","OK"))) -> Crítico | Q5: =IF(A5="","",IF(OR(H5="Atrasado",K5="Sin venta",N5="Pendiente relevante",P5="Crítico"),"Alta",IF(OR(K5="Venta baja",N5="Pendiente menor",P5="Observar"),"Media","Baja"))) -> Alta | R5: =IF(A5="","",IF(Q5="Alta","Gestionar esta semana",IF(Q5="Media","Hacer seguimiento","Mantener"))) -> Gestionar esta semana | S5: =IF(A5="","",IF(I5=0,"Sin venta",IF(I5>=cfg_VentaAlta,"Alta",IF(I5<cfg_VentaBaja,"Baja","Media")))) -> Baja | T5: =IF(A5="","",IFERROR(VLOOKUP(A5,Clientes_PDV!$A$2:$K$250,11,FALSE),"")) -> 0
A6: =IF(Clientes_PDV!A6="","",Clientes_PDV!A6) -> PDV-005 | B6: =IF(A6="","",IFERROR(VLOOKUP(A6,Clientes_PDV!$A$2:$J$250,2,FALSE),"")) -> Get It | C6: =IF(A6="","",IFERROR(VLOOKUP(A6,Clientes_PDV!$A$2:$J$250,3,FALSE),"")) -> Conveniencia | D6: =IF(A6="","",IFERROR(VLOOKUP(A6,Clientes_PDV!$A$2:$J$250,4,FALSE),"")) -> Get It Vitacura | E6: =IF(A6="","",IFERROR(VLOOKUP(A6,Clientes_PDV!$A$2:$J$250,7,FALSE),"")) -> Quincenal | F6: =IF(A6="","",IFERROR(VLOOKUP(A6,Clientes_PDV!$A$2:$J$250,8,FALSE),"")) -> 46191 | G6: =IF(F6="","",TODAY()-F6) -> 22 | H6: =IF(A6="","",IF(F6="","Sin visita",IF(G6<=IFERROR(VLOOKUP(E6,Inicio!$A$24:$B$26,2,FALSE),0),"Vigente","Atrasado"))) -> Atrasado | I6: =IF(A6="","",SUMIFS(Ventas_SellIn!$L$2:$L$800,Ventas_SellIn!$D$2:$D$800,A6,Ventas_SellIn!$B$2:$B$800,">="&TODAY()-Inicio!$B$14)) -> 588968 | J6: =IF(A6="","",SUMIFS(SellOut_Jumbo!$F$2:$F$800,SellOut_Jumbo!$C$2:$C$800,D6,SellOut_Jumbo!$A$2:$A$800,">="&TODAY()-Inicio!$B$14)) -> 0 | K6: =IF(A6="","",IF(I6=0,"Sin venta",IF(I6<Inicio!$B$15,"Venta baja","Venta OK"))) -> Venta OK | L6: =IF(A6="","",COUNTIFS(Ventas_SellIn!$D$2:$D$800,A6,Ventas_SellIn!$R$2:$R$800,">0")) -> 4 | M6: =IF(A6="","",SUMIFS(Ventas_SellIn!$R$2:$R$800,Ventas_SellIn!$D$2:$D$800,A6)) -> 1178554.6 | N6: =IF(A6="","",IF(M6>=Inicio!$B$18,"Pendiente relevante",IF(M6>0,"Pendiente menor","Sin deuda"))) -> Pendiente relevante | O6: =IF(A6="","",SUMIFS(Stock_PDV!$H$2:$H$800,Stock_PDV!$A$2:$A$800,A6)) -> 200 | P6: =IF(A6="","",IF(O6<=Inicio!$B$16,"Crítico",IF(O6<=Inicio!$B$17,"Observar","OK"))) -> OK | Q6: =IF(A6="","",IF(OR(H6="Atrasado",K6="Sin venta",N6="Pendiente relevante",P6="Crítico"),"Alta",IF(OR(K6="Venta baja",N6="Pendiente menor",P6="Observar"),"Media","Baja"))) -> Alta | R6: =IF(A6="","",IF(Q6="Alta","Gestionar esta semana",IF(Q6="Media","Hacer seguimiento","Mantener"))) -> Gestionar esta semana | S6: =IF(A6="","",IF(I6=0,"Sin venta",IF(I6>=cfg_VentaAlta,"Alta",IF(I6<cfg_VentaBaja,"Baja","Media")))) -> Media | T6: =IF(A6="","",IFERROR(VLOOKUP(A6,Clientes_PDV!$A$2:$K$250,11,FALSE),"")) -> 0
